Workbook
Name ARR_DROP_IN_MACHINE: LIST!$D$173:$D$179
Name ARR_DROP_IN_MANUAL: LIST!$E$173:$E$179
Name ARR_FOAM: LIST!$C$173:$C$179
Name BC_ALSTROEMERIA: BICOLOR!$B$2:$B$13
Name BC_ASIATIC: BICOLOR!$C$2:$C$2
Name BC_BONBON_DISBUD: BICOLOR!$K$2:$K$3
Name BC_BRASSICAS: BICOLOR!$D$2:$D$2
Name BC_CALLAS: BICOLOR!$E$2:$E$2
Name BC_CARNATION: BICOLOR!$F$2:$F$33
Name BC_CORDYLINE: BICOLOR!$G$2:$G$3
Name BC_CREMON: BICOLOR!$H$2:$H$5
Name BC_CUSHION: BICOLOR!$I$2:$I$6
Name BC_DAISY: BICOLOR!$J$2:$J$9
Name BC_GERBERA: BICOLOR!$L$2:$L$12
Name BC_GERBERA_GERRONDO: BICOLOR!$M$2:$M$3
Name BC_HYDRANGEA: BICOLOR!$N$2:$N$3
Name BC_LILLY_GRASS: BICOLOR!$P$2:$P$3
Name BC_LIRIOS: BICOLOR!$X$2:$X$2
Name BC_MATSUMOTO: BICOLOR!$W$2:$W$2
Name BC_MINICARNATION: BICOLOR!$Q$2:$Q$25
Name BC_NOVELTY: BICOLOR!$R$2:$R$6
Name BC_ROSES: BICOLOR!$S$2:$S$19
Name BC_ROSES_SPRAY: BICOLOR!$V$2:$V$10
Name BC_SNAP_DRAGON: BICOLOR!$T$2:$T$2
Name BC_SPIDER: BICOLOR!$U$2:$U$4
Name BICOLOR: BICOLOR!$O$2:$O$3
Name CASES: LIST!$A$130:$H$141
Name CLEAR_COLOR: LIST!$A$1
Name CO_ALSTROEMERIA: 'FL-CO'!$F$2:$F$17
Name CO_ARALIA: 'FL-CO'!$G$2:$G$2
Name CO_ASIATIC: 'FL-CO'!$H$2:$H$11
Name CO_ASPIDISTRA: 'FL-CO'!$I$2:$I$3
Name CO_ASTER: 'FL-CO'!$J$2:$J$12
Name CO_BONBON_DISBUD: 'FL-CO'!$W$2:$W$7
Name CO_BRASSICAS: 'FL-CO'!$K$2:$K$6
Name CO_BUTTON: 'FL-CO'!$L$2:$L$10
Name CO_CALLAS: 'FL-CO'!$BG$2:$BG$2
Name CO_CARNATION: 'FL-CO'!$M$2:$M$21
Name CO_CEDAR: 'FL-CO'!$N$2:$N$2
Name CO_COCCULOS: 'FL-CO'!$O$2:$O$2
Name CO_CORDYLINE: 'FL-CO'!$P$2:$P$5
Name CO_CREMON: 'FL-CO'!$Q$2:$Q$15
Name CO_CROTTON: 'FL-CO'!$R$2:$R$3
Name CO_CUSHION: 'FL-CO'!$S$2:$S$19
Name CO_DAISY: 'FL-CO'!$T$2:$T$15
Name CO_DIANTHUS: 'FL-CO'!$V$2:$V$7
Name CO_ERYNGIUM: 'FL-CO'!$X$2:$X$7
Name CO_EUCALIPTUS: 'FL-CO'!$Y$2:$Y$2
Name CO_GARDEN_ROSES: 'FL-CO'!$Z$2:$Z$10
Name CO_GERBERA: 'FL-CO'!$AA$2:$AA$19
Name CO_GERBERA_GERONDO: 'FL-CO'!$AB$2:$AB$6
Name CO_GREVILLEAS: 'FL-CO'!$AC$2:$AC$2
Name CO_GYPSOPHILA: 'FL-CO'!$AD$2:$AD$5
Name CO_HYDRANGEA: 'FL-CO'!$AE$2:$AE$12
Name CO_HYPERYCUM: 'FL-CO'!$AF$2:$AF$17
Name CO_LEATHER_LEAF: 'FL-CO'!$AG$2:$AG$2
Name CO_LEUCADENDRON: 'FL-CO'!$AH$2:$AH$3
Name CO_LILLY_GRASS: 'FL-CO'!$AI$2:$AI$2
Name CO_LIMONIUM: 'FL-CO'!$AJ$2:$AJ$10
Name CO_MATSUMOTO: 'FL-CO'!$AK$2:$AK$10

Sheet Quote
N1: VOL FULL INBOUND | O1: VOL FULL TRANSFER | P1: VOL WP | Q1: INBOUND(U$) | R1: TNT | S1: GLI | T1: TNT + GLT | U1: BIC
AG2: FOB FACILITY FINAL PRICE | AI2: =AI6+(AI6*AI4)+(SUM($AI$9:$AI$11)*SUM($M$15:$M$41)) -> 0.6486 | AL2: MARGIN | AM2: =IFERROR((AM4-AI6-(SUM($AI$9:$AI$11)*SUM($M$15:$M$41)))/AI6,0) -> 16.712766 | AN2: =IF(AM2<10%,"MUST BE OVER 10% - ASK MARAY","")
C3: NAME: | D3: 12.99 BOSS DAY | J3: STEM COUNT | K3: =SUM(C:C) -> 0
Z4: INBOUND - BOX TYPE | AA4: BOX SIZE | AB4: CUFT PER CASE | AC4: BOXES PER PALLET | AG4: MARGIN | AI4: 0.15 | AL4: FOB FACILITY FINAL PRICE | AM4: 9.99
C6: HOLIDAY : | D6: FALL COLORS | Z6: QUARTER | AA6: =VLOOKUP(Z6,DP_FB_RELATION,2,FALSE) -> #N/A | AB6: =VLOOKUP(Z6,DP_FB_RELATION,4,FALSE) -> #N/A | AC6: =VLOOKUP(Z6,DP_FB_RELATION,7,FALSE) -> #N/A | AG6: TOTAL COST FOB FACILITY | AI6: =+AD37+AD48+AD49 -> 0.564
C7: CUSTOMER | D7: PUBLIX
Z8: SUG PACK (DRY) | AA8: PACK DRY | AB8: PACK FB
C9: ORIGEN: | D9: COLOMBIA | Z9: =ROUND(AB9/VLOOKUP(Z6,DP_FB_RELATION,3,FALSE),0) -> #N/A | AA9: 7 | AB9: =IFERROR(ROUND(1/SUM(N:N),0),0) -> 0 | AG9: WASTE % | AI9: 0.01
C10: Type | D10: BOUQUET | AG10: CREDITS % | AI10: 0.005
AG11: FEES | AI11: 0
Z12: FLOWER COST FOB COL | AD12: =SUM($M$15:$M$41) -> 0
Z13: INBOUND USA FREIGHT COST | AD13: =IFERROR(VLOOKUP($D$6,LIST!$A$111:$E$116,MATCH($D$9,LIST!$A$110:$E$110,0),FALSE)*VLOOKUP($Z$6,DP_FB_RELATION,4,FALSE)/VLOOKUP("FULL",DP_FB_RELATION,4,FALSE)/$AA$9,0) -> 0 | AK13: WAREHOUSE | AL13: LOCATION | AM13: $ / CUBE | AN13: $ / CASE | AO13: $ / BUNCH | AP13: DELIVERED COST
C14: STEMS | D14: FLOWER | E14: TINT | F14: GLI | G14: BIC | H14: COLOR | I14: GLITTER | J14: COMMENTS | K14: GRADE | L14: COST | M14: TOTAL | R14: TNT | S14: GLIT | U14: BIC | W14: VLOOKUP | X14: USA COST | Z14: FLOWER | AD14: COST | AG14: MIAMI | AH14: MIA | AI14: %
A15: 1 | B15: =IFERROR(VLOOKUP(D15,LIST!$A$2:$B$86,2,FALSE),"") | L15: =_xlfn.IFNA(SUM(IF($D$6=$J$44,VLOOKUP($D15,'FL COST'!$A$1:$G$81,2,FALSE),IF($D$6=$J$45,VLOOKUP($D15,'FL COST'!$A$1:$G$81,3,FALSE),IF($D$6=$J$46,VLOOKUP($D15,'FL COST'!$A$1:$G$81,4,FALSE),IF($D$6=$J$47,VLOOKUP($D15,'FL COST'!$A$1:$G$81,5,FALSE),IF($D$6=$J$48,VLOOKUP($D15,'FL COST'!$A$1:$G$81,6,FALSE),IF($D$6=$J$49,VLOOKUP($D15,'FL COST'!$A$1:$G$81,7,FALSE),0))))))+IF(E15="Y",0.02,0)+IF(F15="Y",0.02,0)),0) -> 0 | M15: =IFERROR(C15*L15,"ERROR") -> 0 | N15: =IFERROR(SUM($C15/VLOOKUP($D15,PACK!A:B,2,FALSE)),0) -> 0 | O15: =IFERROR(SUM($C15/VLOOKUP($D15,PACK!A:B,2,FALSE)),0) -> 0 | P15: =C15*1/VLOOKUP(D15,PACK!A:B,9,FALSE) -> #N/A | Q15: =IF(C15<>0,N15*VLOOKUP($D$6,FB_COST,3,FALSE),0) -> 0 | R15: =ISNUMBER(MATCH("TNT_"&B15,TINTED!$B$1:$Y$1,0)) -> FALSE | S15: =ISNUMBER(MATCH("GLT_"&B15,GLITTERED!$B$1:$S$1,0)) -> FALSE | U15: =ISNUMBER(MATCH("BC_"&B15,BICOLOR!$B$1:$Y$1,0)) -> FALSE | W15: =IFERROR(IF(VLOOKUP(D15,FL_COST_COL,2,FALSE)="USA","USA","COL"),"") | X15: =IF(K15<>"","$","NO") -> NO | Z15: FLOWER COST FOB MIA | AD15: =+SUM(AD12:AD13) -> 0 | AF15: MIAMI | AG15: TRANSFER COST | AH15: =IFERROR(VLOOKUP($Z$6,DP_FB_RELATION,4,FALSE)*VLOOKUP(AH14,LIST!$A$121:$C$126,3,FALSE)/VLOOKUP("FULL",DP_FB_RELATION,4,FALSE)/$AA$9,0) -> 0 | AI15: 1 | AJ15: 1 | AK15: =IFERROR(VLOOKUP(AJ15&"-"&$D$7,'CUST DATAB'!B:E,3,FALSE),"") -> MIAMI | AL15: =IFERROR(VLOOKUP(AJ15&"-"&$D$7,'CUST DATAB'!B:E,4,FALSE),"") -> ORLANDO | AM15: =IFERROR(IF(VLOOKUP($AK15,$AF$15:$AI$42,4,FALSE)<>0,IF(AL15<>"",VLOOKUP(AL15,'CUST DATAB'!E:F,2,FALSE),""),""),"") -> 0 | AN15: =IF(AM15<>"",AM15*IF($AA$40="y",VLOOKUP($AA$42,CASES,4,FALSE),IF($AA$40="n",VLOOKUP($Z$6,DP_FB_RELATION,4,FALSE))),"") -> #N/A | AO15: =IF(AN15<>"",AN15/IF($AA$40="y",$AB$45,IF($AA$40="n",$AA$9)),"") -> #N/A | AP15: =IF(AO15<>"",$AI$2+AO15,"") -> #N/A
A16: 2 | B16: =IFERROR(VLOOKUP(D16,LIST!$A$2:$B$86,2,FALSE),"") | L16: =_xlfn.IFNA(SUM(IF($D$6=$J$44,VLOOKUP($D16,'FL COST'!$A$1:$G$81,2,FALSE),IF($D$6=$J$45,VLOOKUP($D16,'FL COST'!$A$1:$G$81,3,FALSE),IF($D$6=$J$46,VLOOKUP($D16,'FL COST'!$A$1:$G$81,4,FALSE),IF($D$6=$J$47,VLOOKUP($D16,'FL COST'!$A$1:$G$81,5,FALSE),IF($D$6=$J$48,VLOOKUP($D16,'FL COST'!$A$1:$G$81,6,FALSE),IF($D$6=$J$49,VLOOKUP($D16,'FL COST'!$A$1:$G$81,7,FALSE),0))))))+IF(E16="Y",0.02,0)+IF(F16="Y",0.02,0)),0) -> 0 | M16: =IFERROR(C16*L16,"ERROR") -> 0 | N16: =IFERROR(SUM($C16/VLOOKUP($D16,PACK!A:B,2,FALSE)),0) -> 0 | O16: =IFERROR(SUM($C16/VLOOKUP($D16,PACK!A:B,2,FALSE)),0) -> 0 | P16: =C16*1/VLOOKUP(D16,PACK!A:B,9,FALSE) -> #N/A | Q16: =IF(C16<>0,N16*VLOOKUP($D$6,FB_COST,3,FALSE),0) -> 0 | R16: =ISNUMBER(MATCH("TNT_"&B16,TINTED!$B$1:$Y$1,0)) -> FALSE | S16: =ISNUMBER(MATCH("GLT_"&B16,GLITTERED!$B$1:$S$1,0)) -> FALSE | U16: =ISNUMBER(MATCH("BC_"&B16,BICOLOR!$B$1:$Y$1,0)) -> FALSE | W16: =IFERROR(IF(VLOOKUP(D16,FL_COST_COL,2,FALSE)="USA","USA","COL"),"") | X16: =IF(K16<>"","$","NO") -> NO | AG16: HAND LABOR | AH16: =IF(AND($AA$40="y",$Y$43="WP"),(VLOOKUP(AH14&" _ "&$AA$41,LIST!$A$183:$J$224,MATCH($D$6,LIST!$A$182:$J$182,0),FALSE)-VLOOKUP($AA$42,LIST!$A$130:$H$141,5,FALSE)-VLOOKUP($AA$42,LIST!$A$130:$H$141,8,FALSE))/$AB$45,IF(AND($AA$40="y",$Y$43="ARR"),VLOOKUP(AH14&" _ "&$AA$41,LIST!$A$183:$J$224,MATCH($D$6,LIST!$A$182:$J$182,0),FALSE),0)) -> 0 | AJ16: 2 | AK16: =IFERROR(VLOOKUP(AJ16&"-"&$D$7,'CUST DATAB'!B:E,3,FALSE),"") -> MIAMI | AL16: =IFERROR(VLOOKUP(AJ16&"-"&$D$7,'CUST DATAB'!B:E,4,FALSE),"") -> JACKSONVILLE | AM16: =IFERROR(IF(VLOOKUP($AK16,$AF$15:$AI$42,4,FALSE)<>0,IF(AL16<>"",VLOOKUP(AL16,'CUST DATAB'!E:F,2,FALSE),""),""),"") -> 0 | AN16: =IF(AM16<>"",AM16*IF($AA$40="y",VLOOKUP($AA$42,CASES,4,FALSE),IF($AA$40="n",VLOOKUP($Z$6,DP_FB_RELATION,4,FALSE))),"") -> #N/A | AO16: =IF(AN16<>"",AN16/IF($AA$40="y",$AB$45,IF($AA$40="n",$AA$9)),"") -> #N/A | AP16: =IF(AO16<>"",$AI$2+AO16,"") -> #N/A
A17: 3 | B17: =IFERROR(VLOOKUP(D17,LIST!$A$2:$B$86,2,FALSE),"") | L17: =_xlfn.IFNA(SUM(IF($D$6=$J$44,VLOOKUP($D17,'FL COST'!$A$1:$G$81,2,FALSE),IF($D$6=$J$45,VLOOKUP($D17,'FL COST'!$A$1:$G$81,3,FALSE),IF($D$6=$J$46,VLOOKUP($D17,'FL COST'!$A$1:$G$81,4,FALSE),IF($D$6=$J$47,VLOOKUP($D17,'FL COST'!$A$1:$G$81,5,FALSE),IF($D$6=$J$48,VLOOKUP($D17,'FL COST'!$A$1:$G$81,6,FALSE),IF($D$6=$J$49,VLOOKUP($D17,'FL COST'!$A$1:$G$81,7,FALSE),0))))))+IF(E17="Y",0.02,0)+IF(F17="Y",0.02,0)),0) -> 0 | M17: =IFERROR(C17*L17,"ERROR") -> 0 | N17: =IFERROR(SUM($C17/VLOOKUP($D17,PACK!A:B,2,FALSE)),0) -> 0 | O17: =IFERROR(SUM($C17/VLOOKUP($D17,PACK!A:B,2,FALSE)),0) -> 0 | P17: =C17*1/VLOOKUP(D17,PACK!A:B,9,FALSE) -> #N/A | Q17: =IF(C17<>0,N17*VLOOKUP($D$6,FB_COST,3,FALSE),0) -> 0 | R17: =ISNUMBER(MATCH("TNT_"&B17,TINTED!$B$1:$Y$1,0)) -> FALSE | S17: =ISNUMBER(MATCH("GLT_"&B17,GLITTERED!$B$1:$S$1,0)) -> FALSE | U17: =ISNUMBER(MATCH("BC_"&B17,BICOLOR!$B$1:$Y$1,0)) -> FALSE | W17: =IFERROR(IF(VLOOKUP(D17,FL_COST_COL,2,FALSE)="USA","USA","COL"),"") | X17: =IF(K17<>"","$","NO") -> NO | Z17: DRY MATERIAL COST PER BUNCH | AB17: COST | AC17: Y/N | AD17: TOTAL | AG17: SUB TOTAL | AH17: =+$AD$34+$AD$48+AH15+AH16 -> 0.564 | AJ17: 3 | AK17: =IFERROR(VLOOKUP(AJ17&"-"&$D$7,'CUST DATAB'!B:E,3,FALSE),"") -> MIAMI | AL17: =IFERROR(VLOOKUP(AJ17&"-"&$D$7,'CUST DATAB'!B:E,4,FALSE),"") -> ATLANTA | AM17: =IFERROR(IF(VLOOKUP($AK17,$AF$15:$AI$42,4,FALSE)<>0,IF(AL17<>"",VLOOKUP(AL17,'CUST DATAB'!E:F,2,FALSE),""),""),"") -> 0 | AN17: =IF(AM17<>"",AM17*IF($AA$40="y",VLOOKUP($AA$42,CASES,4,FALSE),IF($AA$40="n",VLOOKUP($Z$6,DP_FB_RELATION,4,FALSE))),"") -> #N/A | AO17: =IF(AN17<>"",AN17/IF($AA$40="y",$AB$45,IF($AA$40="n",$AA$9)),"") -> #N/A | AP17: =IF(AO17<>"",$AI$2+AO17,"") -> #N/A
A18: 4 | B18: =IFERROR(VLOOKUP(D18,LIST!$A$2:$B$86,2,FALSE),"") | L18: =_xlfn.IFNA(SUM(IF($D$6=$J$44,VLOOKUP($D18,'FL COST'!$A$1:$G$81,2,FALSE),IF($D$6=$J$45,VLOOKUP($D18,'FL COST'!$A$1:$G$81,3,FALSE),IF($D$6=$J$46,VLOOKUP($D18,'FL COST'!$A$1:$G$81,4,FALSE),IF($D$6=$J$47,VLOOKUP($D18,'FL COST'!$A$1:$G$81,5,FALSE),IF($D$6=$J$48,VLOOKUP($D18,'FL COST'!$A$1:$G$81,6,FALSE),IF($D$6=$J$49,VLOOKUP($D18,'FL COST'!$A$1:$G$81,7,FALSE),0))))))+IF(E18="Y",0.02,0)+IF(F18="Y",0.02,0)),0) -> 0 | M18: =IFERROR(C18*L18,"ERROR") -> 0 | N18: =IFERROR(SUM($C18/VLOOKUP($D18,PACK!A:B,2,FALSE)),0) -> 0 | O18: =IFERROR(SUM($C18/VLOOKUP($D18,PACK!A:B,2,FALSE)),0) -> 0 | P18: =C18*1/VLOOKUP(D18,PACK!A:B,9,FALSE) -> #N/A | Q18: =IF(C18<>0,N18*VLOOKUP($D$6,FB_COST,3,FALSE),0) -> 0 | R18: =ISNUMBER(MATCH("TNT_"&B18,TINTED!$B$1:$Y$1,0)) -> FALSE | S18: =ISNUMBER(MATCH("GLT_"&B18,GLITTERED!$B$1:$S$1,0)) -> FALSE | U18: =ISNUMBER(MATCH("BC_"&B18,BICOLOR!$B$1:$Y$1,0)) -> FALSE | W18: =IFERROR(IF(VLOOKUP(D18,FL_COST_COL,2,FALSE)="USA","USA","COL"),"") | X18: =IF(K18<>"","$","NO") -> NO | Z18: Clear Sleeve | AB18: 0.06 | AC18: N | AD18: =IF(AC18="Y",AB18,"") | AE18: Clear Sleeve | AJ18: 4 | AK18: =IFERROR(VLOOKUP(AJ18&"-"&$D$7,'CUST DATAB'!B:E,3,FALSE),"") -> MIAMI | AL18: =IFERROR(VLOOKUP(AJ18&"-"&$D$7,'CUST DATAB'!B:E,4,FALSE),"") -> LAKELAND | AM18: =IFERROR(IF(VLOOKUP($AK18,$AF$15:$AI$42,4,FALSE)<>0,IF(AL18<>"",VLOOKUP(AL18,'CUST DATAB'!E:F,2,FALSE),""),""),"") -> 0 | AN18: =IF(AM18<>"",AM18*IF($AA$40="y",VLOOKUP($AA$42,CASES,4,FALSE),IF($AA$40="n",VLOOKUP($Z$6,DP_FB_RELATION,4,FALSE))),"") -> #N/A | AO18: =IF(AN18<>"",AN18/IF($AA$40="y",$AB$45,IF($AA$40="n",$AA$9)),"") -> #N/A | AP18: =IF(AO18<>"",$AI$2+AO18,"") -> #N/A
A19: 5 | B19: =IFERROR(VLOOKUP(D19,LIST!$A$2:$B$86,2,FALSE),"") | L19: =_xlfn.IFNA(SUM(IF($D$6=$J$44,VLOOKUP($D19,'FL COST'!$A$1:$G$81,2,FALSE),IF($D$6=$J$45,VLOOKUP($D19,'FL COST'!$A$1:$G$81,3,FALSE),IF($D$6=$J$46,VLOOKUP($D19,'FL COST'!$A$1:$G$81,4,FALSE),IF($D$6=$J$47,VLOOKUP($D19,'FL COST'!$A$1:$G$81,5,FALSE),IF($D$6=$J$48,VLOOKUP($D19,'FL COST'!$A$1:$G$81,6,FALSE),IF($D$6=$J$49,VLOOKUP($D19,'FL COST'!$A$1:$G$81,7,FALSE),0))))))+IF(E19="Y",0.02,0)+IF(F19="Y",0.02,0)),0) -> 0 | M19: =IFERROR(C19*L19,"ERROR") -> 0 | N19: =IFERROR(SUM($C19/VLOOKUP($D19,PACK!A:B,2,FALSE)),0) -> 0 | O19: =IFERROR(SUM($C19/VLOOKUP($D19,PACK!A:B,2,FALSE)),0) -> 0 | P19: =C19*1/VLOOKUP(D19,PACK!A:B,9,FALSE) -> #N/A | Q19: =IF(C19<>0,N19*VLOOKUP($D$6,FB_COST,3,FALSE),0) -> 0 | R19: =ISNUMBER(MATCH("TNT_"&B19,TINTED!$B$1:$Y$1,0)) -> FALSE | S19: =ISNUMBER(MATCH("GLT_"&B19,GLITTERED!$B$1:$S$1,0)) -> FALSE | U19: =ISNUMBER(MATCH("BC_"&B19,BICOLOR!$B$1:$Y$1,0)) -> FALSE | W19: =IFERROR(IF(VLOOKUP(D19,FL_COST_COL,2,FALSE)="USA","USA","COL"),"") | X19: =IF(K19<>"","$","NO") -> NO | Z19: Clear Sleeve Large | AB19: 0.08 | AC19: N | AD19: =IF(AC19="Y",AB19,"") | AE19: Clear Sleeve Large | AG19: NEW JERSEY | AH19: NJ | AI19: % | AJ19: 5 | AK19: =IFERROR(VLOOKUP(AJ19&"-"&$D$7,'CUST DATAB'!B:E,3,FALSE),"") -> MIAMI | AL19: =IFERROR(VLOOKUP(AJ19&"-"&$D$7,'CUST DATAB'!B:E,4,FALSE),"") -> MIAMI | AM19: =IFERROR(IF(VLOOKUP($AK19,$AF$15:$AI$42,4,FALSE)<>0,IF(AL19<>"",VLOOKUP(AL19,'CUST DATAB'!E:F,2,FALSE),""),""),"") -> 0 | AN19: =IF(AM19<>"",AM19*IF($AA$40="y",VLOOKUP($AA$42,CASES,4,FALSE),IF($AA$40="n",VLOOKUP($Z$6,DP_FB_RELATION,4,FALSE))),"") -> #N/A | AO19: =IF(AN19<>"",AN19/IF($AA$40="y",$AB$45,IF($AA$40="n",$AA$9)),"") -> #N/A | AP19: =IF(AO19<>"",$AI$2+AO19,"") -> #N/A
A20: 6 | B20: =IFERROR(VLOOKUP(D20,LIST!$A$2:$B$86,2,FALSE),"") | L20: =_xlfn.IFNA(SUM(IF($D$6=$J$44,VLOOKUP($D20,'FL COST'!$A$1:$G$81,2,FALSE),IF($D$6=$J$45,VLOOKUP($D20,'FL COST'!$A$1:$G$81,3,FALSE),IF($D$6=$J$46,VLOOKUP($D20,'FL COST'!$A$1:$G$81,4,FALSE),IF($D$6=$J$47,VLOOKUP($D20,'FL COST'!$A$1:$G$81,5,FALSE),IF($D$6=$J$48,VLOOKUP($D20,'FL COST'!$A$1:$G$81,6,FALSE),IF($D$6=$J$49,VLOOKUP($D20,'FL COST'!$A$1:$G$81,7,FALSE),0))))))+IF(E20="Y",0.02,0)+IF(F20="Y",0.02,0)),0) -> 0 | M20: =IFERROR(C20*L20,"ERROR") -> 0 | N20: =IFERROR(SUM($C20/VLOOKUP($D20,PACK!A:B,2,FALSE)),0) -> 0 | O20: =IFERROR(SUM($C20/VLOOKUP($D20,PACK!A:B,2,FALSE)),0) -> 0 | P20: =C20*1/VLOOKUP(D20,PACK!A:B,9,FALSE) -> #N/A | Q20: =IF(C20<>0,N20*VLOOKUP($D$6,FB_COST,3,FALSE),0) -> 0 | R20: =ISNUMBER(MATCH("TNT_"&B20,TINTED!$B$1:$Y$1,0)) -> FALSE | S20: =ISNUMBER(MATCH("GLT_"&B20,GLITTERED!$B$1:$S$1,0)) -> FALSE | U20: =ISNUMBER(MATCH("BC_"&B20,BICOLOR!$B$1:$Y$1,0)) -> FALSE | W20: =IFERROR(IF(VLOOKUP(D20,FL_COST_COL,2,FALSE)="USA","USA","COL"),"") | X20: =IF(K20<>"","$","NO") -> NO | Z20: Food | AB20: 0.054 | AC20: Y | AD20: =IF(AC20="Y",AB20,"") -> 0.054 | AE20: Food | AG20: TRANSFER COST | AH20: =IFERROR(VLOOKUP($Z$6,DP_FB_RELATION,4,FALSE)*VLOOKUP(AH19,LIST!$A$121:$C$126,3,FALSE)/VLOOKUP("FULL",DP_FB_RELATION,4,FALSE)/$AA$9,0) -> 0 | AI20: 0 | AJ20: 6 | AK20: =IFERROR(VLOOKUP(AJ20&"-"&$D$7,'CUST DATAB'!B:E,3,FALSE),"") | AL20: =IFERROR(VLOOKUP(AJ20&"-"&$D$7,'CUST DATAB'!B:E,4,FALSE),"") | AM20: =IFERROR(IF(VLOOKUP($AK20,$AF$15:$AI$42,4,FALSE)<>0,IF(AL20<>"",VLOOKUP(AL20,'CUST DATAB'!E:F,2,FALSE),""),""),"") | AN20: =IF(AM20<>"",AM20*IF($AA$40="y",VLOOKUP($AA$42,CASES,4,FALSE),IF($AA$40="n",VLOOKUP($Z$6,DP_FB_RELATION,4,FALSE))),"") | AO20: =IF(AN20<>"",AN20/IF($AA$40="y",$AB$45,IF($AA$40="n",$AA$9)),"") | AP20: =IF(AO20<>"",$AI$2+AO20,"")
A21: 7 | B21: =IFERROR(VLOOKUP(D21,LIST!$A$2:$B$86,2,FALSE),"") | L21: =_xlfn.IFNA(SUM(IF($D$6=$J$44,VLOOKUP($D21,'FL COST'!$A$1:$G$81,2,FALSE),IF($D$6=$J$45,VLOOKUP($D21,'FL COST'!$A$1:$G$81,3,FALSE),IF($D$6=$J$46,VLOOKUP($D21,'FL COST'!$A$1:$G$81,4,FALSE),IF($D$6=$J$47,VLOOKUP($D21,'FL COST'!$A$1:$G$81,5,FALSE),IF($D$6=$J$48,VLOOKUP($D21,'FL COST'!$A$1:$G$81,6,FALSE),IF($D$6=$J$49,VLOOKUP($D21,'FL COST'!$A$1:$G$81,7,FALSE),0))))))+IF(E21="Y",0.02,0)+IF(F21="Y",0.02,0)),0) -> 0 | M21: =IFERROR(C21*L21,"ERROR") -> 0 | N21: =IFERROR(SUM($C21/VLOOKUP($D21,PACK!A:B,2,FALSE)),0) -> 0 | O21: =IFERROR(SUM($C21/VLOOKUP($D21,PACK!A:B,2,FALSE)),0) -> 0 | P21: =C21*1/VLOOKUP(D21,PACK!A:B,9,FALSE) -> #N/A | Q21: =IF(C21<>0,N21*VLOOKUP($D$6,FB_COST,3,FALSE),0) -> 0 | R21: =ISNUMBER(MATCH("TNT_"&B21,TINTED!$B$1:$Y$1,0)) -> FALSE | S21: =ISNUMBER(MATCH("GLT_"&B21,GLITTERED!$B$1:$S$1,0)) -> FALSE | U21: =ISNUMBER(MATCH("BC_"&B21,BICOLOR!$B$1:$Y$1,0)) -> FALSE | W21: =IFERROR(IF(VLOOKUP(D21,FL_COST_COL,2,FALSE)="USA","USA","COL"),"") | X21: =IF(K21<>"","$","NO") -> NO | Z21: UPC | AB21: 0.01 | AC21: Y | AD21: =IF(AC21="Y",AB21,"") -> 0.01 | AE21: UPC | AG21: HAND LABOR | AH21: =IF(AND($AA$40="y",$Y$43="WP"),(VLOOKUP(AH19&" _ "&$AA$41,LIST!$A$183:$J$224,MATCH($D$6,LIST!$A$182:$J$182,0),FALSE)-VLOOKUP($AA$42,LIST!$A$130:$H$141,5,FALSE)-VLOOKUP($AA$42,LIST!$A$130:$H$141,8,FALSE))/$AB$45,IF(AND($AA$40="y",$Y$43="ARR"),VLOOKUP(AH19&" _ "&$AA$41,LIST!$A$183:$J$224,MATCH($D$6,LIST!$A$182:$J$182,0),FALSE),0)) -> 0 | AJ21: 7 | AK21: =IFERROR(VLOOKUP(AJ21&"-"&$D$7,'CUST DATAB'!B:E,3,FALSE),"") | AL21: =IFERROR(VLOOKUP(AJ21&"-"&$D$7,'CUST DATAB'!B:E,4,FALSE),"") | AM21: =IFERROR(IF(VLOOKUP($AK21,$AF$15:$AI$42,4,FALSE)<>0,IF(AL21<>"",VLOOKUP(AL21,'CUST DATAB'!E:F,2,FALSE),""),""),"") | AN21: =IF(AM21<>"",AM21*IF($AA$40="y",VLOOKUP($AA$42,CASES,4,FALSE),IF($AA$40="n",VLOOKUP($Z$6,DP_FB_RELATION,4,FALSE))),"") | AO21: =IF(AN21<>"",AN21/IF($AA$40="y",$AB$45,IF($AA$40="n",$AA$9)),"") | AP21: =IF(AO21<>"",$AI$2+AO21,"")
A22: 8 | B22: =IFERROR(VLOOKUP(D22,LIST!$A$2:$B$86,2,FALSE),"") | L22: =_xlfn.IFNA(SUM(IF($D$6=$J$44,VLOOKUP($D22,'FL COST'!$A$1:$G$81,2,FALSE),IF($D$6=$J$45,VLOOKUP($D22,'FL COST'!$A$1:$G$81,3,FALSE),IF($D$6=$J$46,VLOOKUP($D22,'FL COST'!$A$1:$G$81,4,FALSE),IF($D$6=$J$47,VLOOKUP($D22,'FL COST'!$A$1:$G$81,5,FALSE),IF($D$6=$J$48,VLOOKUP($D22,'FL COST'!$A$1:$G$81,6,FALSE),IF($D$6=$J$49,VLOOKUP($D22,'FL COST'!$A$1:$G$81,7,FALSE),0))))))+IF(E22="Y",0.02,0)+IF(F22="Y",0.02,0)),0) -> 0 | M22: =IFERROR(C22*L22,"ERROR") -> 0 | N22: =IFERROR(SUM($C22/VLOOKUP($D22,PACK!A:B,2,FALSE)),0) -> 0 | O22: =IFERROR(SUM($C22/VLOOKUP($D22,PACK!A:B,2,FALSE)),0) -> 0 | P22: =C22*1/VLOOKUP(D22,PACK!A:B,9,FALSE) -> #N/A | Q22: =IF(C22<>0,N22*VLOOKUP($D$6,FB_COST,3,FALSE),0) -> 0 | R22: =ISNUMBER(MATCH("TNT_"&B22,TINTED!$B$1:$Y$1,0)) -> FALSE | S22: =ISNUMBER(MATCH("GLT_"&B22,GLITTERED!$B$1:$S$1,0)) -> FALSE | U22: =ISNUMBER(MATCH("BC_"&B22,BICOLOR!$B$1:$Y$1,0)) -> FALSE | W22: =IFERROR(IF(VLOOKUP(D22,FL_COST_COL,2,FALSE)="USA","USA","COL"),"") | X22: =IF(K22<>"","$","NO") -> NO | Z22: Arrangement Bag | AB22: 1.5 | AC22: N | AD22: =IF(AC22="Y",AB22,"") | AE22: Arrangement Bag | AG22: SUB TOTAL | AH22: =+$AD$34+$AD$48+AH20+AH21 -> 0.564 | AJ22: 8 | AK22: =IFERROR(VLOOKUP(AJ22&"-"&$D$7,'CUST DATAB'!B:E,3,FALSE),"") | AL22: =IFERROR(VLOOKUP(AJ22&"-"&$D$7,'CUST DATAB'!B:E,4,FALSE),"") | AM22: =IFERROR(IF(VLOOKUP($AK22,$AF$15:$AI$42,4,FALSE)<>0,IF(AL22<>"",VLOOKUP(AL22,'CUST DATAB'!E:F,2,FALSE),""),""),"") | AN22: =IF(AM22<>"",AM22*IF($AA$40="y",VLOOKUP($AA$42,CASES,4,FALSE),IF($AA$40="n",VLOOKUP($Z$6,DP_FB_RELATION,4,FALSE))),"") | AO22: =IF(AN22<>"",AN22/IF($AA$40="y",$AB$45,IF($AA$40="n",$AA$9)),"") | AP22: =IF(AO22<>"",$AI$2+AO22,"")
A23: 9 | B23: =IFERROR(VLOOKUP(D23,LIST!$A$2:$B$86,2,FALSE),"") | L23: =_xlfn.IFNA(SUM(IF($D$6=$J$44,VLOOKUP($D23,'FL COST'!$A$1:$G$81,2,FALSE),IF($D$6=$J$45,VLOOKUP($D23,'FL COST'!$A$1:$G$81,3,FALSE),IF($D$6=$J$46,VLOOKUP($D23,'FL COST'!$A$1:$G$81,4,FALSE),IF($D$6=$J$47,VLOOKUP($D23,'FL COST'!$A$1:$G$81,5,FALSE),IF($D$6=$J$48,VLOOKUP($D23,'FL COST'!$A$1:$G$81,6,FALSE),IF($D$6=$J$49,VLOOKUP($D23,'FL COST'!$A$1:$G$81,7,FALSE),0))))))+IF(E23="Y",0.02,0)+IF(F23="Y",0.02,0)),0) -> 0 | M23: =IFERROR(C23*L23,"ERROR") -> 0 | N23: =IFERROR(SUM($C23/VLOOKUP($D23,PACK!A:B,2,FALSE)),0) -> 0 | O23: =IFERROR(SUM($C23/VLOOKUP($D23,PACK!A:B,2,FALSE)),0) -> 0 | P23: =C23*1/VLOOKUP(D23,PACK!A:B,9,FALSE) -> #N/A | Q23: =IF(C23<>0,N23*VLOOKUP($D$6,FB_COST,3,FALSE),0) -> 0 | R23: =ISNUMBER(MATCH("TNT_"&B23,TINTED!$B$1:$Y$1,0)) -> FALSE | S23: =ISNUMBER(MATCH("GLT_"&B23,GLITTERED!$B$1:$S$1,0)) -> FALSE | U23: =ISNUMBER(MATCH("BC_"&B23,BICOLOR!$B$1:$Y$1,0)) -> FALSE | W23: =IFERROR(IF(VLOOKUP(D23,FL_COST_COL,2,FALSE)="USA","USA","COL"),"") | X23: =IF(K23<>"","$","NO") -> NO | Z23: Pick | AB23: 0.35 | AC23: n | AD23: =IF(AC23="Y",AB23,"") | AE23: Pick | AJ23: 9 | AK23: =IFERROR(VLOOKUP(AJ23&"-"&$D$7,'CUST DATAB'!B:E,3,FALSE),"") | AL23: =IFERROR(VLOOKUP(AJ23&"-"&$D$7,'CUST DATAB'!B:E,4,FALSE),"") | AM23: =IFERROR(IF(VLOOKUP($AK23,$AF$15:$AI$42,4,FALSE)<>0,IF(AL23<>"",VLOOKUP(AL23,'CUST DATAB'!E:F,2,FALSE),""),""),"") | AN23: =IF(AM23<>"",AM23*IF($AA$40="y",VLOOKUP($AA$42,CASES,4,FALSE),IF($AA$40="n",VLOOKUP($Z$6,DP_FB_RELATION,4,FALSE))),"") | AO23: =IF(AN23<>"",AN23/IF($AA$40="y",$AB$45,IF($AA$40="n",$AA$9)),"") | AP23: =IF(AO23<>"",$AI$2+AO23,"")
A24: 10 | B24: =IFERROR(VLOOKUP(D24,LIST!$A$2:$B$86,2,FALSE),"") | L24: =_xlfn.IFNA(SUM(IF($D$6=$J$44,VLOOKUP($D24,'FL COST'!$A$1:$G$81,2,FALSE),IF($D$6=$J$45,VLOOKUP($D24,'FL COST'!$A$1:$G$81,3,FALSE),IF($D$6=$J$46,VLOOKUP($D24,'FL COST'!$A$1:$G$81,4,FALSE),IF($D$6=$J$47,VLOOKUP($D24,'FL COST'!$A$1:$G$81,5,FALSE),IF($D$6=$J$48,VLOOKUP($D24,'FL COST'!$A$1:$G$81,6,FALSE),IF($D$6=$J$49,VLOOKUP($D24,'FL COST'!$A$1:$G$81,7,FALSE),0))))))+IF(E24="Y",0.02,0)+IF(F24="Y",0.02,0)),0) -> 0 | M24: =IFERROR(C24*L24,"ERROR") -> 0 | N24: =IFERROR(SUM($C24/VLOOKUP($D24,PACK!A:B,2,FALSE)),0) -> 0 | O24: =IFERROR(SUM($C24/VLOOKUP($D24,PACK!A:B,2,FALSE)),0) -> 0 | P24: =C24*1/VLOOKUP(D24,PACK!A:B,9,FALSE) -> #N/A | Q24: =IF(C24<>0,N24*VLOOKUP($D$6,FB_COST,3,FALSE),0) -> 0 | R24: =ISNUMBER(MATCH("TNT_"&B24,TINTED!$B$1:$Y$1,0)) -> FALSE | S24: =ISNUMBER(MATCH("GLT_"&B24,GLITTERED!$B$1:$S$1,0)) -> FALSE | U24: =ISNUMBER(MATCH("BC_"&B24,BICOLOR!$B$1:$Y$1,0)) -> FALSE | W24: =IFERROR(IF(VLOOKUP(D24,FL_COST_COL,2,FALSE)="USA","USA","COL"),"") | X24: =IF(K24<>"","$","NO") -> NO | Z24: Scent | AB24: 0.1 | AD24: =IF(AC24="Y",AB24,"") | AE24: Scent | AG24: CALIFORNIA | AH24: LAX | AI24: % | AJ24: 10 | AK24: =IFERROR(VLOOKUP(AJ24&"-"&$D$7,'CUST DATAB'!B:E,3,FALSE),"") | AL24: =IFERROR(VLOOKUP(AJ24&"-"&$D$7,'CUST DATAB'!B:E,4,FALSE),"") | AM24: =IFERROR(IF(VLOOKUP($AK24,$AF$15:$AI$42,4,FALSE)<>0,IF(AL24<>"",VLOOKUP(AL24,'CUST DATAB'!E:F,2,FALSE),""),""),"") | AN24: =IF(AM24<>"",AM24*IF($AA$40="y",VLOOKUP($AA$42,CASES,4,FALSE),IF($AA$40="n",VLOOKUP($Z$6,DP_FB_RELATION,4,FALSE))),"") | AO24: =IF(AN24<>"",AN24/IF($AA$40="y",$AB$45,IF($AA$40="n",$AA$9)),"") | AP24: =IF(AO24<>"",$AI$2+AO24,"")
A25: 11 | B25: =IFERROR(VLOOKUP(D25,LIST!$A$2:$B$86,2,FALSE),"") | L25: =_xlfn.IFNA(SUM(IF($D$6=$J$44,VLOOKUP($D25,'FL COST'!$A$1:$G$81,2,FALSE),IF($D$6=$J$45,VLOOKUP($D25,'FL COST'!$A$1:$G$81,3,FALSE),IF($D$6=$J$46,VLOOKUP($D25,'FL COST'!$A$1:$G$81,4,FALSE),IF($D$6=$J$47,VLOOKUP($D25,'FL COST'!$A$1:$G$81,5,FALSE),IF($D$6=$J$48,VLOOKUP($D25,'FL COST'!$A$1:$G$81,6,FALSE),IF($D$6=$J$49,VLOOKUP($D25,'FL COST'!$A$1:$G$81,7,FALSE),0))))))+IF(E25="Y",0.02,0)+IF(F25="Y",0.02,0)),0) -> 0 | M25: =IFERROR(C25*L25,"ERROR") -> 0 | N25: =IFERROR(SUM($C25/VLOOKUP($D25,PACK!A:B,2,FALSE)),0) -> 0 | O25: =IFERROR(SUM($C25/VLOOKUP($D25,PACK!A:B,2,FALSE)),0) -> 0 | P25: =C25*1/VLOOKUP(D25,PACK!A:B,9,FALSE) -> #N/A | Q25: =IF(C25<>0,N25*VLOOKUP($D$6,FB_COST,3,FALSE),0) -> 0 | R25: =ISNUMBER(MATCH("TNT_"&B25,TINTED!$B$1:$Y$1,0)) -> FALSE | S25: =ISNUMBER(MATCH("GLT_"&B25,GLITTERED!$B$1:$S$1,0)) -> FALSE | U25: =ISNUMBER(MATCH("BC_"&B25,BICOLOR!$B$1:$Y$1,0)) -> FALSE | W25: =IFERROR(IF(VLOOKUP(D25,FL_COST_COL,2,FALSE)="USA","USA","COL"),"") | X25: =IF(K25<>"","$","NO") -> NO | Z25: Wrap / Sleeve | AB25: 0.5 | AC25: Y | AD25: =IF(AC25="Y",AB25,"") -> 0.5 | AE25: Wrap / Sleeve | AG25: TRANSFER COST | AH25: =IFERROR(VLOOKUP($Z$6,DP_FB_RELATION,4,FALSE)*VLOOKUP(AH24,LIST!$A$121:$C$126,3,FALSE)/VLOOKUP("FULL",DP_FB_RELATION,4,FALSE)/$AA$9,0) -> 0 | AI25: 0 | AJ25: 11 | AK25: =IFERROR(VLOOKUP(AJ25&"-"&$D$7,'CUST DATAB'!B:E,3,FALSE),"") | AL25: =IFERROR(VLOOKUP(AJ25&"-"&$D$7,'CUST DATAB'!B:E,4,FALSE),"") | AM25: =IFERROR(IF(VLOOKUP($AK25,$AF$15:$AI$42,4,FALSE)<>0,IF(AL25<>"",VLOOKUP(AL25,'CUST DATAB'!E:F,2,FALSE),""),""),"") | AN25: =IF(AM25<>"",AM25*IF($AA$40="y",VLOOKUP($AA$42,CASES,4,FALSE),IF($AA$40="n",VLOOKUP($Z$6,DP_FB_RELATION,4,FALSE))),"") | AO25: =IF(AN25<>"",AN25/IF($AA$40="y",$AB$45,IF($AA$40="n",$AA$9)),"") | AP25: =IF(AO25<>"",$AI$2+AO25,"")
A26: 12 | B26: =IFERROR(VLOOKUP(D26,LIST!$A$2:$B$86,2,FALSE),"") | L26: =_xlfn.IFNA(SUM(IF($D$6=$J$44,VLOOKUP($D26,'FL COST'!$A$1:$G$81,2,FALSE),IF($D$6=$J$45,VLOOKUP($D26,'FL COST'!$A$1:$G$81,3,FALSE),IF($D$6=$J$46,VLOOKUP($D26,'FL COST'!$A$1:$G$81,4,FALSE),IF($D$6=$J$47,VLOOKUP($D26,'FL COST'!$A$1:$G$81,5,FALSE),IF($D$6=$J$48,VLOOKUP($D26,'FL COST'!$A$1:$G$81,6,FALSE),IF($D$6=$J$49,VLOOKUP($D26,'FL COST'!$A$1:$G$81,7,FALSE),0))))))+IF(E26="Y",0.02,0)+IF(F26="Y",0.02,0)),0) -> 0 | M26: =IFERROR(C26*L26,"ERROR") -> 0 | N26: =IFERROR(SUM($C26/VLOOKUP($D26,PACK!A:B,2,FALSE)),0) -> 0 | O26: =IFERROR(SUM($C26/VLOOKUP($D26,PACK!A:B,2,FALSE)),0) -> 0 | P26: =C26*1/VLOOKUP(D26,PACK!A:B,9,FALSE) -> #N/A | Q26: =IF(C26<>0,N26*VLOOKUP($D$6,FB_COST,3,FALSE),0) -> 0 | R26: =ISNUMBER(MATCH("TNT_"&B26,TINTED!$B$1:$Y$1,0)) -> FALSE | S26: =ISNUMBER(MATCH("GLT_"&B26,GLITTERED!$B$1:$S$1,0)) -> FALSE | U26: =ISNUMBER(MATCH("BC_"&B26,BICOLOR!$B$1:$Y$1,0)) -> FALSE | W26: =IFERROR(IF(VLOOKUP(D26,FL_COST_COL,2,FALSE)="USA","USA","COL"),"") | X26: =IF(K26<>"","$","NO") -> NO | Z26: Card | AB26: 0.15 | AD26: =IF(AC26="Y",AB26,"") | AE26: Card | AG26: HAND LABOR | AH26: =IF(AND($AA$40="y",$Y$43="WP"),(VLOOKUP(AH24&" _ "&$AA$41,LIST!$A$183:$J$224,MATCH($D$6,LIST!$A$182:$J$182,0),FALSE)-VLOOKUP($AA$42,LIST!$A$130:$H$141,5,FALSE)-VLOOKUP($AA$42,LIST!$A$130:$H$141,8,FALSE))/$AB$45,IF(AND($AA$40="y",$Y$43="ARR"),VLOOKUP(AH24&" _ "&$AA$41,LIST!$A$183:$J$224,MATCH($D$6,LIST!$A$182:$J$182,0),FALSE),0)) -> 0 | AJ26: 12 | AK26: =IFERROR(VLOOKUP(AJ26&"-"&$D$7,'CUST DATAB'!B:E,3,FALSE),"") | AL26: =IFERROR(VLOOKUP(AJ26&"-"&$D$7,'CUST DATAB'!B:E,4,FALSE),"") | AM26: =IFERROR(IF(VLOOKUP($AK26,$AF$15:$AI$42,4,FALSE)<>0,IF(AL26<>"",VLOOKUP(AL26,'CUST DATAB'!E:F,2,FALSE),""),""),"") | AN26: =IF(AM26<>"",AM26*IF($AA$40="y",VLOOKUP($AA$42,CASES,4,FALSE),IF($AA$40="n",VLOOKUP($Z$6,DP_FB_RELATION,4,FALSE))),"") | AO26: =IF(AN26<>"",AN26/IF($AA$40="y",$AB$45,IF($AA$40="n",$AA$9)),"") | AP26: =IF(AO26<>"",$AI$2+AO26,"")
A27: 13 | B27: =IFERROR(VLOOKUP(D27,LIST!$A$2:$B$86,2,FALSE),"") | L27: =_xlfn.IFNA(SUM(IF($D$6=$J$44,VLOOKUP($D27,'FL COST'!$A$1:$G$81,2,FALSE),IF($D$6=$J$45,VLOOKUP($D27,'FL COST'!$A$1:$G$81,3,FALSE),IF($D$6=$J$46,VLOOKUP($D27,'FL COST'!$A$1:$G$81,4,FALSE),IF($D$6=$J$47,VLOOKUP($D27,'FL COST'!$A$1:$G$81,5,FALSE),IF($D$6=$J$48,VLOOKUP($D27,'FL COST'!$A$1:$G$81,6,FALSE),IF($D$6=$J$49,VLOOKUP($D27,'FL COST'!$A$1:$G$81,7,FALSE),0))))))+IF(E27="Y",0.02,0)+IF(F27="Y",0.02,0)),0) -> 0 | M27: =IFERROR(C27*L27,"ERROR") -> 0 | N27: =IFERROR(SUM($C27/VLOOKUP($D27,PACK!A:B,2,FALSE)),0) -> 0 | O27: =IFERROR(SUM($C27/VLOOKUP($D27,PACK!A:B,2,FALSE)),0) -> 0 | P27: =C27*1/VLOOKUP(D27,PACK!A:B,9,FALSE) -> #N/A | Q27: =IF(C27<>0,N27*VLOOKUP($D$6,FB_COST,3,FALSE),0) -> 0 | R27: =ISNUMBER(MATCH("TNT_"&B27,TINTED!$B$1:$Y$1,0)) -> FALSE | S27: =ISNUMBER(MATCH("GLT_"&B27,GLITTERED!$B$1:$S$1,0)) -> FALSE | U27: =ISNUMBER(MATCH("BC_"&B27,BICOLOR!$B$1:$Y$1,0)) -> FALSE | W27: =IFERROR(IF(VLOOKUP(D27,FL_COST_COL,2,FALSE)="USA","USA","COL"),"") | X27: =IF(K27<>"","$","NO") -> NO | Z27: Vase / Bowl / Recipient | AB27: 1 | AC27: N | AD27: =IF(AC27="Y",AB27,"") | AE27: Vase / Bowl / Recipient | AG27: SUB TOTAL | AH27: =+$AD$34+$AD$48+AH25+AH26 -> 0.564 | AJ27: 13 | AK27: =IFERROR(VLOOKUP(AJ27&"-"&$D$7,'CUST DATAB'!B:E,3,FALSE),"") | AL27: =IFERROR(VLOOKUP(AJ27&"-"&$D$7,'CUST DATAB'!B:E,4,FALSE),"") | AM27: =IFERROR(IF(VLOOKUP($AK27,$AF$15:$AI$42,4,FALSE)<>0,IF(AL27<>"",VLOOKUP(AL27,'CUST DATAB'!E:F,2,FALSE),""),""),"") | AN27: =IF(AM27<>"",AM27*IF($AA$40="y",VLOOKUP($AA$42,CASES,4,FALSE),IF($AA$40="n",VLOOKUP($Z$6,DP_FB_RELATION,4,FALSE))),"") | AO27: =IF(AN27<>"",AN27/IF($AA$40="y",$AB$45,IF($AA$40="n",$AA$9)),"") | AP27: =IF(AO27<>"",$AI$2+AO27,"")
A28: 14 | B28: =IFERROR(VLOOKUP(D28,LIST!$A$2:$B$86,2,FALSE),"") | L28: =_xlfn.IFNA(SUM(IF($D$6=$J$44,VLOOKUP($D28,'FL COST'!$A$1:$G$81,2,FALSE),IF($D$6=$J$45,VLOOKUP($D28,'FL COST'!$A$1:$G$81,3,FALSE),IF($D$6=$J$46,VLOOKUP($D28,'FL COST'!$A$1:$G$81,4,FALSE),IF($D$6=$J$47,VLOOKUP($D28,'FL COST'!$A$1:$G$81,5,FALSE),IF($D$6=$J$48,VLOOKUP($D28,'FL COST'!$A$1:$G$81,6,FALSE),IF($D$6=$J$49,VLOOKUP($D28,'FL COST'!$A$1:$G$81,7,FALSE),0))))))+IF(E28="Y",0.02,0)+IF(F28="Y",0.02,0)),0) -> 0 | M28: =IFERROR(C28*L28,"ERROR") -> 0 | N28: =IFERROR(SUM($C28/VLOOKUP($D28,PACK!A:B,2,FALSE)),0) -> 0 | O28: =IFERROR(SUM($C28/VLOOKUP($D28,PACK!A:B,2,FALSE)),0) -> 0 | P28: =C28*1/VLOOKUP(D28,PACK!A:B,9,FALSE) -> #N/A | Q28: =IF(C28<>0,N28*VLOOKUP($D$6,FB_COST,3,FALSE),0) -> 0 | R28: =ISNUMBER(MATCH("TNT_"&B28,TINTED!$B$1:$Y$1,0)) -> FALSE | S28: =ISNUMBER(MATCH("GLT_"&B28,GLITTERED!$B$1:$S$1,0)) -> FALSE | U28: =ISNUMBER(MATCH("BC_"&B28,BICOLOR!$B$1:$Y$1,0)) -> FALSE | W28: =IFERROR(IF(VLOOKUP(D28,FL_COST_COL,2,FALSE)="USA","USA","COL"),"") | X28: =IF(K28<>"","$","NO") -> NO | Z28: Foam | AD28: =IF(AC28="Y",AB28,"") | AE28: Foam | AJ28: 14 | AK28: =IFERROR(VLOOKUP(AJ28&"-"&$D$7,'CUST DATAB'!B:E,3,FALSE),"") | AL28: =IFERROR(VLOOKUP(AJ28&"-"&$D$7,'CUST DATAB'!B:E,4,FALSE),"") | AM28: =IFERROR(IF(VLOOKUP($AK28,$AF$15:$AI$42,4,FALSE)<>0,IF(AL28<>"",VLOOKUP(AL28,'CUST DATAB'!E:F,2,FALSE),""),""),"") | AN28: =IF(AM28<>"",AM28*IF($AA$40="y",VLOOKUP($AA$42,CASES,4,FALSE),IF($AA$40="n",VLOOKUP($Z$6,DP_FB_RELATION,4,FALSE))),"") | AO28: =IF(AN28<>"",AN28/IF($AA$40="y",$AB$45,IF($AA$40="n",$AA$9)),"") | AP28: =IF(AO28<>"",$AI$2+AO28,"")
A29: 15 | B29: =IFERROR(VLOOKUP(D29,LIST!$A$2:$B$86,2,FALSE),"") | L29: =_xlfn.IFNA(SUM(IF($D$6=$J$44,VLOOKUP($D29,'FL COST'!$A$1:$G$81,2,FALSE),IF($D$6=$J$45,VLOOKUP($D29,'FL COST'!$A$1:$G$81,3,FALSE),IF($D$6=$J$46,VLOOKUP($D29,'FL COST'!$A$1:$G$81,4,FALSE),IF($D$6=$J$47,VLOOKUP($D29,'FL COST'!$A$1:$G$81,5,FALSE),IF($D$6=$J$48,VLOOKUP($D29,'FL COST'!$A$1:$G$81,6,FALSE),IF($D$6=$J$49,VLOOKUP($D29,'FL COST'!$A$1:$G$81,7,FALSE),0))))))+IF(E29="Y",0.02,0)+IF(F29="Y",0.02,0)),0) -> 0 | M29: =IFERROR(C29*L29,"ERROR") -> 0 | N29: =IFERROR(SUM($C29/VLOOKUP($D29,PACK!A:B,2,FALSE)),0) -> 0 | O29: =IFERROR(SUM($C29/VLOOKUP($D29,PACK!A:B,2,FALSE)),0) -> 0 | P29: =C29*1/VLOOKUP(D29,PACK!A:B,9,FALSE) -> #N/A | Q29: =IF(C29<>0,N29*VLOOKUP($D$6,FB_COST,3,FALSE),0) -> 0 | R29: =ISNUMBER(MATCH("TNT_"&B29,TINTED!$B$1:$Y$1,0)) -> FALSE | S29: =ISNUMBER(MATCH("GLT_"&B29,GLITTERED!$B$1:$S$1,0)) -> FALSE | U29: =ISNUMBER(MATCH("BC_"&B29,BICOLOR!$B$1:$Y$1,0)) -> FALSE | W29: =IFERROR(IF(VLOOKUP(D29,FL_COST_COL,2,FALSE)="USA","USA","COL"),"") | X29: =IF(K29<>"","$","NO") -> NO | Z29: Bag | AB29: 1 | AD29: =IF(AC29="Y",AB29,"") | AE29: Bag | AG29: CHICAGO | AH29: CH | AI29: % | AJ29: 15 | AK29: =IFERROR(VLOOKUP(AJ29&"-"&$D$7,'CUST DATAB'!B:E,3,FALSE),"") | AL29: =IFERROR(VLOOKUP(AJ29&"-"&$D$7,'CUST DATAB'!B:E,4,FALSE),"") | AM29: =IFERROR(IF(VLOOKUP($AK29,$AF$15:$AI$42,4,FALSE)<>0,IF(AL29<>"",VLOOKUP(AL29,'CUST DATAB'!E:F,2,FALSE),""),""),"") | AN29: =IF(AM29<>"",AM29*IF($AA$40="y",VLOOKUP($AA$42,CASES,4,FALSE),IF($AA$40="n",VLOOKUP($Z$6,DP_FB_RELATION,4,FALSE))),"") | AO29: =IF(AN29<>"",AN29/IF($AA$40="y",$AB$45,IF($AA$40="n",$AA$9)),"") | AP29: =IF(AO29<>"",$AI$2+AO29,"")
A30: 16 | B30: =IFERROR(VLOOKUP(D30,LIST!$A$2:$B$86,2,FALSE),"") | L30: =_xlfn.IFNA(SUM(IF($D$6=$J$44,VLOOKUP($D30,'FL COST'!$A$1:$G$81,2,FALSE),IF($D$6=$J$45,VLOOKUP($D30,'FL COST'!$A$1:$G$81,3,FALSE),IF($D$6=$J$46,VLOOKUP($D30,'FL COST'!$A$1:$G$81,4,FALSE),IF($D$6=$J$47,VLOOKUP($D30,'FL COST'!$A$1:$G$81,5,FALSE),IF($D$6=$J$48,VLOOKUP($D30,'FL COST'!$A$1:$G$81,6,FALSE),IF($D$6=$J$49,VLOOKUP($D30,'FL COST'!$A$1:$G$81,7,FALSE),0))))))+IF(E30="Y",0.02,0)+IF(F30="Y",0.02,0)),0) -> 0 | M30: =IFERROR(C30*L30,"ERROR") -> 0 | N30: =IFERROR(SUM($C30/VLOOKUP($D30,PACK!A:B,2,FALSE)),0) -> 0 | O30: =IFERROR(SUM($C30/VLOOKUP($D30,PACK!A:B,2,FALSE)),0) -> 0 | P30: =C30*1/VLOOKUP(D30,PACK!A:B,9,FALSE) -> #N/A | Q30: =IF(C30<>0,N30*VLOOKUP($D$6,FB_COST,3,FALSE),0) -> 0 | R30: =ISNUMBER(MATCH("TNT_"&B30,TINTED!$B$1:$Y$1,0)) -> FALSE | S30: =ISNUMBER(MATCH("GLT_"&B30,GLITTERED!$B$1:$S$1,0)) -> FALSE | U30: =ISNUMBER(MATCH("BC_"&B30,BICOLOR!$B$1:$Y$1,0)) -> FALSE | W30: =IFERROR(IF(VLOOKUP(D30,FL_COST_COL,2,FALSE)="USA","USA","COL"),"") | X30: =IF(K30<>"","$","NO") -> NO | Z30: Other 1 | AD30: =IF(AC30="Y",AB30,"") | AE30: Other 1 | AG30: TRANSFER COST | AH30: =IFERROR(VLOOKUP($Z$6,DP_FB_RELATION,4,FALSE)*VLOOKUP(AH29,LIST!$A$121:$C$126,3,FALSE)/VLOOKUP("FULL",DP_FB_RELATION,4,FALSE)/$AA$9,0) -> 0 | AI30: 0 | AJ30: 16 | AK30: =IFERROR(VLOOKUP(AJ30&"-"&$D$7,'CUST DATAB'!B:E,3,FALSE),"") | AL30: =IFERROR(VLOOKUP(AJ30&"-"&$D$7,'CUST DATAB'!B:E,4,FALSE),"") | AM30: =IFERROR(IF(VLOOKUP($AK30,$AF$15:$AI$42,4,FALSE)<>0,IF(AL30<>"",VLOOKUP(AL30,'CUST DATAB'!E:F,2,FALSE),""),""),"") | AN30: =IF(AM30<>"",AM30*IF($AA$40="y",VLOOKUP($AA$42,CASES,4,FALSE),IF($AA$40="n",VLOOKUP($Z$6,DP_FB_RELATION,4,FALSE))),"") | AO30: =IF(AN30<>"",AN30/IF($AA$40="y",$AB$45,IF($AA$40="n",$AA$9)),"") | AP30: =IF(AO30<>"",$AI$2+AO30,"")
A31: 17 | B31: =IFERROR(VLOOKUP(D31,LIST!$A$2:$B$86,2,FALSE),"") | L31: =_xlfn.IFNA(SUM(IF($D$6=$J$44,VLOOKUP($D31,'FL COST'!$A$1:$G$81,2,FALSE),IF($D$6=$J$45,VLOOKUP($D31,'FL COST'!$A$1:$G$81,3,FALSE),IF($D$6=$J$46,VLOOKUP($D31,'FL COST'!$A$1:$G$81,4,FALSE),IF($D$6=$J$47,VLOOKUP($D31,'FL COST'!$A$1:$G$81,5,FALSE),IF($D$6=$J$48,VLOOKUP($D31,'FL COST'!$A$1:$G$81,6,FALSE),IF($D$6=$J$49,VLOOKUP($D31,'FL COST'!$A$1:$G$81,7,FALSE),0))))))+IF(E31="Y",0.02,0)+IF(F31="Y",0.02,0)),0) -> 0 | M31: =IFERROR(C31*L31,"ERROR") -> 0 | N31: =IFERROR(SUM($C31/VLOOKUP($D31,PACK!A:B,2,FALSE)),0) -> 0 | O31: =IFERROR(SUM($C31/VLOOKUP($D31,PACK!A:B,2,FALSE)),0) -> 0 | P31: =C31*1/VLOOKUP(D31,PACK!A:B,9,FALSE) -> #N/A | Q31: =IF(C31<>0,N31*VLOOKUP($D$6,FB_COST,3,FALSE),0) -> 0 | R31: =ISNUMBER(MATCH("TNT_"&B31,TINTED!$B$1:$Y$1,0)) -> FALSE | S31: =ISNUMBER(MATCH("GLT_"&B31,GLITTERED!$B$1:$S$1,0)) -> FALSE | U31: =ISNUMBER(MATCH("BC_"&B31,BICOLOR!$B$1:$Y$1,0)) -> FALSE | W31: =IFERROR(IF(VLOOKUP(D31,FL_COST_COL,2,FALSE)="USA","USA","COL"),"") | X31: =IF(K31<>"","$","NO") -> NO | Z31: Other 2 | AD31: =IF(AC31="Y",AB31,"") | AE31: Other 2 | AG31: HAND LABOR | AH31: =IF(AND($AA$40="y",$Y$43="WP"),(VLOOKUP(AH29&" _ "&$AA$41,LIST!$A$183:$J$224,MATCH($D$6,LIST!$A$182:$J$182,0),FALSE)-VLOOKUP($AA$42,LIST!$A$130:$H$141,5,FALSE)-VLOOKUP($AA$42,LIST!$A$130:$H$141,8,FALSE))/$AB$45,IF(AND($AA$40="y",$Y$43="ARR"),VLOOKUP(AH29&" _ "&$AA$41,LIST!$A$183:$J$224,MATCH($D$6,LIST!$A$182:$J$182,0),FALSE),0)) -> 0 | AJ31: 17 | AK31: =IFERROR(VLOOKUP(AJ31&"-"&$D$7,'CUST DATAB'!B:E,3,FALSE),"") | AL31: =IFERROR(VLOOKUP(AJ31&"-"&$D$7,'CUST DATAB'!B:E,4,FALSE),"") | AM31: =IFERROR(IF(VLOOKUP($AK31,$AF$15:$AI$42,4,FALSE)<>0,IF(AL31<>"",VLOOKUP(AL31,'CUST DATAB'!E:F,2,FALSE),""),""),"") | AN31: =IF(AM31<>"",AM31*IF($AA$40="y",VLOOKUP($AA$42,CASES,4,FALSE),IF($AA$40="n",VLOOKUP($Z$6,DP_FB_RELATION,4,FALSE))),"") | AO31: =IF(AN31<>"",AN31/IF($AA$40="y",$AB$45,IF($AA$40="n",$AA$9)),"") | AP31: =IF(AO31<>"",$AI$2+AO31,"")
A32: 18 | B32: =IFERROR(VLOOKUP(D32,LIST!$A$2:$B$86,2,FALSE),"") | L32: =_xlfn.IFNA(SUM(IF($D$6=$J$44,VLOOKUP($D32,'FL COST'!$A$1:$G$81,2,FALSE),IF($D$6=$J$45,VLOOKUP($D32,'FL COST'!$A$1:$G$81,3,FALSE),IF($D$6=$J$46,VLOOKUP($D32,'FL COST'!$A$1:$G$81,4,FALSE),IF($D$6=$J$47,VLOOKUP($D32,'FL COST'!$A$1:$G$81,5,FALSE),IF($D$6=$J$48,VLOOKUP($D32,'FL COST'!$A$1:$G$81,6,FALSE),IF($D$6=$J$49,VLOOKUP($D32,'FL COST'!$A$1:$G$81,7,FALSE),0))))))+IF(E32="Y",0.02,0)+IF(F32="Y",0.02,0)),0) -> 0 | M32: =IFERROR(C32*L32,"ERROR") -> 0 | N32: =IFERROR(SUM($C32/VLOOKUP($D32,PACK!A:B,2,FALSE)),0) -> 0 | O32: =IFERROR(SUM($C32/VLOOKUP($D32,PACK!A:B,2,FALSE)),0) -> 0 | P32: =C32*1/VLOOKUP(D32,PACK!A:B,9,FALSE) -> #N/A | Q32: =IF(C32<>0,N32*VLOOKUP($D$6,FB_COST,3,FALSE),0) -> 0 | R32: =ISNUMBER(MATCH("TNT_"&B32,TINTED!$B$1:$Y$1,0)) -> FALSE | S32: =ISNUMBER(MATCH("GLT_"&B32,GLITTERED!$B$1:$S$1,0)) -> FALSE | U32: =ISNUMBER(MATCH("BC_"&B32,BICOLOR!$B$1:$Y$1,0)) -> FALSE | W32: =IFERROR(IF(VLOOKUP(D32,FL_COST_COL,2,FALSE)="USA","USA","COL"),"") | X32: =IF(K32<>"","$","NO") -> NO | Z32: TOTAL DRY GOODS | AD32: =+SUM(AD18:AD31) -> 0.564 | AG32: SUB TOTAL | AH32: =+$AD$34+$AD$48+AH30+AH31 -> 0.564 | AJ32: 18 | AK32: =IFERROR(VLOOKUP(AJ32&"-"&$D$7,'CUST DATAB'!B:E,3,FALSE),"") | AL32: =IFERROR(VLOOKUP(AJ32&"-"&$D$7,'CUST DATAB'!B:E,4,FALSE),"") | AM32: =IFERROR(IF(VLOOKUP($AK32,$AF$15:$AI$42,4,FALSE)<>0,IF(AL32<>"",VLOOKUP(AL32,'CUST DATAB'!E:F,2,FALSE),""),""),"") | AN32: =IF(AM32<>"",AM32*IF($AA$40="y",VLOOKUP($AA$42,CASES,4,FALSE),IF($AA$40="n",VLOOKUP($Z$6,DP_FB_RELATION,4,FALSE))),"") | AO32: =IF(AN32<>"",AN32/IF($AA$40="y",$AB$45,IF($AA$40="n",$AA$9)),"") | AP32: =IF(AO32<>"",$AI$2+AO32,"")
A33: 19 | B33: =IFERROR(VLOOKUP(D33,LIST!$A$2:$B$86,2,FALSE),"") | L33: =_xlfn.IFNA(SUM(IF($D$6=$J$44,VLOOKUP($D33,'FL COST'!$A$1:$G$81,2,FALSE),IF($D$6=$J$45,VLOOKUP($D33,'FL COST'!$A$1:$G$81,3,FALSE),IF($D$6=$J$46,VLOOKUP($D33,'FL COST'!$A$1:$G$81,4,FALSE),IF($D$6=$J$47,VLOOKUP($D33,'FL COST'!$A$1:$G$81,5,FALSE),IF($D$6=$J$48,VLOOKUP($D33,'FL COST'!$A$1:$G$81,6,FALSE),IF($D$6=$J$49,VLOOKUP($D33,'FL COST'!$A$1:$G$81,7,FALSE),0))))))+IF(E33="Y",0.02,0)+IF(F33="Y",0.02,0)),0) -> 0 | M33: =IFERROR(C33*L33,"ERROR") -> 0 | N33: =IFERROR(SUM($C33/VLOOKUP($D33,PACK!A:B,2,FALSE)),0) -> 0 | O33: =IFERROR(SUM($C33/VLOOKUP($D33,PACK!A:B,2,FALSE)),0) -> 0 | P33: =C33*1/VLOOKUP(D33,PACK!A:B,9,FALSE) -> #N/A | Q33: =IF(C33<>0,N33*VLOOKUP($D$6,FB_COST,3,FALSE),0) -> 0 | R33: =ISNUMBER(MATCH("TNT_"&B33,TINTED!$B$1:$Y$1,0)) -> FALSE | S33: =ISNUMBER(MATCH("GLT_"&B33,GLITTERED!$B$1:$S$1,0)) -> FALSE | U33: =ISNUMBER(MATCH("BC_"&B33,BICOLOR!$B$1:$Y$1,0)) -> FALSE | W33: =IFERROR(IF(VLOOKUP(D33,FL_COST_COL,2,FALSE)="USA","USA","COL"),"") | X33: =IF(K33<>"","$","NO") -> NO | AJ33: 19 | AK33: =IFERROR(VLOOKUP(AJ33&"-"&$D$7,'CUST DATAB'!B:E,3,FALSE),"") | AL33: =IFERROR(VLOOKUP(AJ33&"-"&$D$7,'CUST DATAB'!B:E,4,FALSE),"") | AM33: =IFERROR(IF(VLOOKUP($AK33,$AF$15:$AI$42,4,FALSE)<>0,IF(AL33<>"",VLOOKUP(AL33,'CUST DATAB'!E:F,2,FALSE),""),""),"") | AN33: =IF(AM33<>"",AM33*IF($AA$40="y",VLOOKUP($AA$42,CASES,4,FALSE),IF($AA$40="n",VLOOKUP($Z$6,DP_FB_RELATION,4,FALSE))),"") | AO33: =IF(AN33<>"",AN33/IF($AA$40="y",$AB$45,IF($AA$40="n",$AA$9)),"") | AP33: =IF(AO33<>"",$AI$2+AO33,"")
A34: 20 | B34: =IFERROR(VLOOKUP(D34,LIST!$A$2:$B$86,2,FALSE),"") | L34: =_xlfn.IFNA(SUM(IF($D$6=$J$44,VLOOKUP($D34,'FL COST'!$A$1:$G$81,2,FALSE),IF($D$6=$J$45,VLOOKUP($D34,'FL COST'!$A$1:$G$81,3,FALSE),IF($D$6=$J$46,VLOOKUP($D34,'FL COST'!$A$1:$G$81,4,FALSE),IF($D$6=$J$47,VLOOKUP($D34,'FL COST'!$A$1:$G$81,5,FALSE),IF($D$6=$J$48,VLOOKUP($D34,'FL COST'!$A$1:$G$81,6,FALSE),IF($D$6=$J$49,VLOOKUP($D34,'FL COST'!$A$1:$G$81,7,FALSE),0))))))+IF(E34="Y",0.02,0)+IF(F34="Y",0.02,0)),0) -> 0 | M34: =IFERROR(C34*L34,"ERROR") -> 0 | N34: =IFERROR(SUM($C34/VLOOKUP($D34,PACK!A:B,2,FALSE)),0) -> 0 | O34: =IFERROR(SUM($C34/VLOOKUP($D34,PACK!A:B,2,FALSE)),0) -> 0 | P34: =C34*1/VLOOKUP(D34,PACK!A:B,9,FALSE) -> #N/A | Q34: =IF(C34<>0,N34*VLOOKUP($D$6,FB_COST,3,FALSE),0) -> 0 | R34: =ISNUMBER(MATCH("TNT_"&B34,TINTED!$B$1:$Y$1,0)) -> FALSE | S34: =ISNUMBER(MATCH("GLT_"&B34,GLITTERED!$B$1:$S$1,0)) -> FALSE | U34: =ISNUMBER(MATCH("BC_"&B34,BICOLOR!$B$1:$Y$1,0)) -> FALSE | W34: =IFERROR(IF(VLOOKUP(D34,FL_COST_COL,2,FALSE)="USA","USA","COL"),"") | X34: =IF(K34<>"","$","NO") -> NO | Z34: TOTAL MIAMI LANDED COST | AD34: =+AD15+AD32 -> 0.564 | AG34: SEATTLE | AH34: WA | AI34: % | AJ34: 20 | AK34: =IFERROR(VLOOKUP(AJ34&"-"&$D$7,'CUST DATAB'!B:E,3,FALSE),"") | AL34: =IFERROR(VLOOKUP(AJ34&"-"&$D$7,'CUST DATAB'!B:E,4,FALSE),"") | AM34: =IFERROR(IF(VLOOKUP($AK34,$AF$15:$AI$42,4,FALSE)<>0,IF(AL34<>"",VLOOKUP(AL34,'CUST DATAB'!E:F,2,FALSE),""),""),"") | AN34: =IF(AM34<>"",AM34*IF($AA$40="y",VLOOKUP($AA$42,CASES,4,FALSE),IF($AA$40="n",VLOOKUP($Z$6,DP_FB_RELATION,4,FALSE))),"") | AO34: =IF(AN34<>"",AN34/IF($AA$40="y",$AB$45,IF($AA$40="n",$AA$9)),"") | AP34: =IF(AO34<>"",$AI$2+AO34,"")
A35: 21 | B35: =IFERROR(VLOOKUP(D35,LIST!$A$2:$B$86,2,FALSE),"") | L35: =_xlfn.IFNA(SUM(IF($D$6=$J$44,VLOOKUP($D35,'FL COST'!$A$1:$G$81,2,FALSE),IF($D$6=$J$45,VLOOKUP($D35,'FL COST'!$A$1:$G$81,3,FALSE),IF($D$6=$J$46,VLOOKUP($D35,'FL COST'!$A$1:$G$81,4,FALSE),IF($D$6=$J$47,VLOOKUP($D35,'FL COST'!$A$1:$G$81,5,FALSE),IF($D$6=$J$48,VLOOKUP($D35,'FL COST'!$A$1:$G$81,6,FALSE),IF($D$6=$J$49,VLOOKUP($D35,'FL COST'!$A$1:$G$81,7,FALSE),0))))))+IF(E35="Y",0.02,0)+IF(F35="Y",0.02,0)),0) -> 0 | M35: =IFERROR(C35*L35,"ERROR") -> 0 | N35: =IFERROR(SUM($C35/VLOOKUP($D35,PACK!A:B,2,FALSE)),0) -> 0 | O35: =IFERROR(SUM($C35/VLOOKUP($D35,PACK!A:B,2,FALSE)),0) -> 0 | P35: =C35*1/VLOOKUP(D35,PACK!A:B,9,FALSE) -> #N/A | Q35: =IF(C35<>0,N35*VLOOKUP($D$6,FB_COST,3,FALSE),0) -> 0 | R35: =ISNUMBER(MATCH("TNT_"&B35,TINTED!$B$1:$Y$1,0)) -> FALSE | S35: =ISNUMBER(MATCH("GLT_"&B35,GLITTERED!$B$1:$S$1,0)) -> FALSE | U35: =ISNUMBER(MATCH("BC_"&B35,BICOLOR!$B$1:$Y$1,0)) -> FALSE | W35: =IFERROR(IF(VLOOKUP(D35,FL_COST_COL,2,FALSE)="USA","USA","COL"),"") | X35: =IF(K35<>"","$","NO") -> NO | Z35: TRANSFER DRY TO FACILITY COST | AD35: =(AH15*AI15)+(AH20*AI20)+(AH25*AI25)+(AH30*AI30)+(AH35*AI35)+(AH40*AI40) -> 0 | AF35: SEATTLE | AG35: TRANSFER COST | AH35: =IFERROR(VLOOKUP($Z$6,DP_FB_RELATION,4,FALSE)*VLOOKUP(AH34,LIST!$A$121:$C$126,3,FALSE)/VLOOKUP("FULL",DP_FB_RELATION,4,FALSE)/$AA$9,0) -> 0 | AI35: 0 | AJ35: 21 | AK35: =IFERROR(VLOOKUP(AJ35&"-"&$D$7,'CUST DATAB'!B:E,3,FALSE),"") | AL35: =IFERROR(VLOOKUP(AJ35&"-"&$D$7,'CUST DATAB'!B:E,4,FALSE),"") | AM35: =IFERROR(IF(VLOOKUP($AK35,$AF$15:$AI$42,4,FALSE)<>0,IF(AL35<>"",VLOOKUP(AL35,'CUST DATAB'!E:F,2,FALSE),""),""),"") | AN35: =IF(AM35<>"",AM35*IF($AA$40="y",VLOOKUP($AA$42,CASES,4,FALSE),IF($AA$40="n",VLOOKUP($Z$6,DP_FB_RELATION,4,FALSE))),"") | AO35: =IF(AN35<>"",AN35/IF($AA$40="y",$AB$45,IF($AA$40="n",$AA$9)),"") | AP35: =IF(AO35<>"",$AI$2+AO35,"")
A36: 22 | B36: =IFERROR(VLOOKUP(D36,LIST!$A$2:$B$86,2,FALSE),"") | L36: =_xlfn.IFNA(SUM(IF($D$6=$J$44,VLOOKUP($D36,'FL COST'!$A$1:$G$81,2,FALSE),IF($D$6=$J$45,VLOOKUP($D36,'FL COST'!$A$1:$G$81,3,FALSE),IF($D$6=$J$46,VLOOKUP($D36,'FL COST'!$A$1:$G$81,4,FALSE),IF($D$6=$J$47,VLOOKUP($D36,'FL COST'!$A$1:$G$81,5,FALSE),IF($D$6=$J$48,VLOOKUP($D36,'FL COST'!$A$1:$G$81,6,FALSE),IF($D$6=$J$49,VLOOKUP($D36,'FL COST'!$A$1:$G$81,7,FALSE),0))))))+IF(E36="Y",0.02,0)+IF(F36="Y",0.02,0)),0) -> 0 | M36: =IFERROR(C36*L36,"ERROR") -> 0 | N36: =IFERROR(SUM($C36/VLOOKUP($D36,PACK!A:B,2,FALSE)),0) -> 0 | O36: =IFERROR(SUM($C36/VLOOKUP($D36,PACK!A:B,2,FALSE)),0) -> 0 | P36: =C36*1/VLOOKUP(D36,PACK!A:B,9,FALSE) -> #N/A | Q36: =IF(C36<>0,N36*VLOOKUP($D$6,FB_COST,3,FALSE),0) -> 0 | R36: =ISNUMBER(MATCH("TNT_"&B36,TINTED!$B$1:$Y$1,0)) -> FALSE | S36: =ISNUMBER(MATCH("GLT_"&B36,GLITTERED!$B$1:$S$1,0)) -> FALSE | U36: =ISNUMBER(MATCH("BC_"&B36,BICOLOR!$B$1:$Y$1,0)) -> FALSE | W36: =IFERROR(IF(VLOOKUP(D36,FL_COST_COL,2,FALSE)="USA","USA","COL"),"") | X36: =IF(K36<>"","$","NO") -> NO | Z36: Per Stem Cost (Bouquet Only) | AD36: =IF(D10="BOUQUET",SUM(K3*0.06),0) -> 0 | AG36: HAND LABOR | AH36: =IF(AND($AA$40="y",$Y$43="WP"),(VLOOKUP(AH34&" _ "&$AA$41,LIST!$A$183:$J$224,MATCH($D$6,LIST!$A$182:$J$182,0),FALSE)-VLOOKUP($AA$42,LIST!$A$130:$H$141,5,FALSE)-VLOOKUP($AA$42,LIST!$A$130:$H$141,8,FALSE))/$AB$45,IF(AND($AA$40="y",$Y$43="ARR"),VLOOKUP(AH34&" _ "&$AA$41,LIST!$A$183:$J$224,MATCH($D$6,LIST!$A$182:$J$182,0),FALSE),0)) -> 0 | AJ36: 22 | AK36: =IFERROR(VLOOKUP(AJ36&"-"&$D$7,'CUST DATAB'!B:E,3,FALSE),"") | AL36: =IFERROR(VLOOKUP(AJ36&"-"&$D$7,'CUST DATAB'!B:E,4,FALSE),"") | AM36: =IFERROR(IF(VLOOKUP($AK36,$AF$15:$AI$42,4,FALSE)<>0,IF(AL36<>"",VLOOKUP(AL36,'CUST DATAB'!E:F,2,FALSE),""),""),"") | AN36: =IF(AM36<>"",AM36*IF($AA$40="y",VLOOKUP($AA$42,CASES,4,FALSE),IF($AA$40="n",VLOOKUP($Z$6,DP_FB_RELATION,4,FALSE))),"") | AO36: =IF(AN36<>"",AN36/IF($AA$40="y",$AB$45,IF($AA$40="n",$AA$9)),"") | AP36: =IF(AO36<>"",$AI$2+AO36,"")
A37: 23 | B37: =IFERROR(VLOOKUP(D37,LIST!$A$2:$B$86,2,FALSE),"") | L37: =_xlfn.IFNA(SUM(IF($D$6=$J$44,VLOOKUP($D37,'FL COST'!$A$1:$G$81,2,FALSE),IF($D$6=$J$45,VLOOKUP($D37,'FL COST'!$A$1:$G$81,3,FALSE),IF($D$6=$J$46,VLOOKUP($D37,'FL COST'!$A$1:$G$81,4,FALSE),IF($D$6=$J$47,VLOOKUP($D37,'FL COST'!$A$1:$G$81,5,FALSE),IF($D$6=$J$48,VLOOKUP($D37,'FL COST'!$A$1:$G$81,6,FALSE),IF($D$6=$J$49,VLOOKUP($D37,'FL COST'!$A$1:$G$81,7,FALSE),0))))))+IF(E37="Y",0.02,0)+IF(F37="Y",0.02,0)),0) -> 0 | M37: =IFERROR(C37*L37,"ERROR") -> 0 | N37: =IFERROR(SUM($C37/VLOOKUP($D37,PACK!A:B,2,FALSE)),0) -> 0 | O37: =IFERROR(SUM($C37/VLOOKUP($D37,PACK!A:B,2,FALSE)),0) -> 0 | P37: =C37*1/VLOOKUP(D37,PACK!A:B,9,FALSE) -> #N/A | Q37: =IF(C37<>0,N37*VLOOKUP($D$6,FB_COST,3,FALSE),0) -> 0 | R37: =ISNUMBER(MATCH("TNT_"&B37,TINTED!$B$1:$Y$1,0)) -> FALSE | S37: =ISNUMBER(MATCH("GLT_"&B37,GLITTERED!$B$1:$S$1,0)) -> FALSE | U37: =ISNUMBER(MATCH("BC_"&B37,BICOLOR!$B$1:$Y$1,0)) -> FALSE | W37: =IFERROR(IF(VLOOKUP(D37,FL_COST_COL,2,FALSE)="USA","USA","COL"),"") | X37: =IF(K37<>"","$","NO") -> NO | Z37: TOTAL WAREHOUSE LANDED | AD37: =SUM(AD34:AD36) -> 0.564 | AG37: SUB TOTAL | AH37: =+$AD$34+$AD$48+AH35+AH36 -> 0.564 | AJ37: 23 | AK37: =IFERROR(VLOOKUP(AJ37&"-"&$D$7,'CUST DATAB'!B:E,3,FALSE),"") | AL37: =IFERROR(VLOOKUP(AJ37&"-"&$D$7,'CUST DATAB'!B:E,4,FALSE),"") | AM37: =IFERROR(IF(VLOOKUP($AK37,$AF$15:$AI$42,4,FALSE)<>0,IF(AL37<>"",VLOOKUP(AL37,'CUST DATAB'!E:F,2,FALSE),""),""),"") | AN37: =IF(AM37<>"",AM37*IF($AA$40="y",VLOOKUP($AA$42,CASES,4,FALSE),IF($AA$40="n",VLOOKUP($Z$6,DP_FB_RELATION,4,FALSE))),"") | AO37: =IF(AN37<>"",AN37/IF($AA$40="y",$AB$45,IF($AA$40="n",$AA$9)),"") | AP37: =IF(AO37<>"",$AI$2+AO37,"")
A38: 24 | B38: =IFERROR(VLOOKUP(D38,LIST!$A$2:$B$86,2,FALSE),"") | M38: =IFERROR(C38*L38,"ERROR") -> 0 | N38: =+$C38*0.0025 -> 0 | O38: =+$C38*0.0025 -> 0 | P38: =C38*1/120 -> 0 | Q38: =IF(C38<>0,N38*VLOOKUP($D$6,FB_COST,3,FALSE),0) -> 0 | R38: =ISNUMBER(MATCH("TNT_"&B38,TINTED!$B$1:$Y$1,0)) -> FALSE | S38: =ISNUMBER(MATCH("GLT_"&B38,GLITTERED!$B$1:$S$1,0)) -> FALSE | U38: =ISNUMBER(MATCH("BC_"&B38,BICOLOR!$B$1:$Y$1,0)) -> FALSE | W38: =IFERROR(IF(VLOOKUP(D38,FL_COST_COL,2,FALSE)="USA","USA","COL"),"") | X38: =IF(K38<>"","$","NO") -> NO | Y38: =IF(AA38="y","WP_TYPE","no_wp") -> no_wp | AJ38: 24 | AK38: =IFERROR(VLOOKUP(AJ38&"-"&$D$7,'CUST DATAB'!B:E,3,FALSE),"") | AL38: =IFERROR(VLOOKUP(AJ38&"-"&$D$7,'CUST DATAB'!B:E,4,FALSE),"") | AM38: =IFERROR(IF(VLOOKUP($AK38,$AF$15:$AI$42,4,FALSE)<>0,IF(AL38<>"",VLOOKUP(AL38,'CUST DATAB'!E:F,2,FALSE),""),""),"") | AN38: =IF(AM38<>"",AM38*IF($AA$40="y",VLOOKUP($AA$42,CASES,4,FALSE),IF($AA$40="n",VLOOKUP($Z$6,DP_FB_RELATION,4,FALSE))),"") | AO38: =IF(AN38<>"",AN38/IF($AA$40="y",$AB$45,IF($AA$40="n",$AA$9)),"") | AP38: =IF(AO38<>"",$AI$2+AO38,"")
A39: 25 | B39: =IFERROR(VLOOKUP(D39,LIST!$A$2:$B$86,2,FALSE),"") | M39: =IFERROR(C39*L39,"ERROR") -> 0 | N39: =+$C39*0.0025 -> 0 | O39: =+$C39*0.0025 -> 0 | P39: =C39*1/120 -> 0 | Q39: =IF(C39<>0,N39*VLOOKUP($D$6,FB_COST,3,FALSE),0) -> 0 | R39: =ISNUMBER(MATCH("TNT_"&B39,TINTED!$B$1:$Y$1,0)) -> FALSE | S39: =ISNUMBER(MATCH("GLT_"&B39,GLITTERED!$B$1:$S$1,0)) -> FALSE | U39: =ISNUMBER(MATCH("BC_"&B39,BICOLOR!$B$1:$Y$1,0)) -> FALSE | W39: =IFERROR(IF(VLOOKUP(D39,FL_COST_COL,2,FALSE)="USA","USA","COL"),"") | X39: =IF(K39<>"","$","NO") -> NO | Y39: =IF(AA39="y","WP_TYPE","no_wp") -> no_wp | AG39: TEXAS | AH39: TX | AJ39: 25 | AK39: =IFERROR(VLOOKUP(AJ39&"-"&$D$7,'CUST DATAB'!B:E,3,FALSE),"") | AL39: =IFERROR(VLOOKUP(AJ39&"-"&$D$7,'CUST DATAB'!B:E,4,FALSE),"") | AM39: =IFERROR(IF(VLOOKUP($AK39,$AF$15:$AI$42,4,FALSE)<>0,IF(AL39<>"",VLOOKUP(AL39,'CUST DATAB'!E:F,2,FALSE),""),""),"") | AN39: =IF(AM39<>"",AM39*IF($AA$40="y",VLOOKUP($AA$42,CASES,4,FALSE),IF($AA$40="n",VLOOKUP($Z$6,DP_FB_RELATION,4,FALSE))),"") | AO39: =IF(AN39<>"",AN39/IF($AA$40="y",$AB$45,IF($AA$40="n",$AA$9)),"") | AP39: =IF(AO39<>"",$AI$2+AO39,"")
A40: 26 | B40: =IFERROR(VLOOKUP(D40,LIST!$A$2:$B$86,2,FALSE),"") | M40: =IFERROR(C40*L40,"ERROR") -> 0 | N40: =+$C40*0.0025 -> 0 | O40: =+$C40*0.0025 -> 0 | P40: =C40*1/120 -> 0 | Q40: =IF(C40<>0,N40*VLOOKUP($D$6,FB_COST,3,FALSE),0) -> 0 | R40: =ISNUMBER(MATCH("TNT_"&B40,TINTED!$B$1:$Y$1,0)) -> FALSE | S40: =ISNUMBER(MATCH("GLT_"&B40,GLITTERED!$B$1:$S$1,0)) -> FALSE | U40: =ISNUMBER(MATCH("BC_"&B40,BICOLOR!$B$1:$Y$1,0)) -> FALSE | W40: =IFERROR(IF(VLOOKUP(D40,FL_COST_COL,2,FALSE)="USA","USA","COL"),"") | X40: =IF(K40<>"","$","NO") -> NO | Y40: =IF(AA40="y","WP_TYPE","no_wp") -> no_wp | Z40: Is it a Wet Pack ? | AA40: N | AC40: DIMENTIONS | AD40: =IF(AA40="y",VLOOKUP(AA42,CASES,3,FALSE),"") | AF40: TEXAS | AG40: TRANSFER COST | AH40: =IFERROR(VLOOKUP($Z$6,DP_FB_RELATION,4,FALSE)*VLOOKUP(AH39,LIST!$A$121:$C$126,3,FALSE)/VLOOKUP("FULL",DP_FB_RELATION,4,FALSE)/$AA$9,0) -> 0 | AI40: 0 | AJ40: 26 | AK40: =IFERROR(VLOOKUP(AJ40&"-"&$D$7,'CUST DATAB'!B:E,3,FALSE),"") | AL40: =IFERROR(VLOOKUP(AJ40&"-"&$D$7,'CUST DATAB'!B:E,4,FALSE),"") | AM40: =IFERROR(IF(VLOOKUP($AK40,$AF$15:$AI$42,4,FALSE)<>0,IF(AL40<>"",VLOOKUP(AL40,'CUST DATAB'!E:F,2,FALSE),""),""),"") | AN40: =IF(AM40<>"",AM40*IF($AA$40="y",VLOOKUP($AA$42,CASES,4,FALSE),IF($AA$40="n",VLOOKUP($Z$6,DP_FB_RELATION,4,FALSE))),"") | AO40: =IF(AN40<>"",AN40/IF($AA$40="y",$AB$45,IF($AA$40="n",$AA$9)),"") | AP40: =IF(AO40<>"",$AI$2+AO40,"")
A41: 27 | B41: =IFERROR(VLOOKUP(D41,LIST!$A$2:$B$86,2,FALSE),"") | M41: =IFERROR(C41*L41,"ERROR") -> 0 | N41: =+$C41*0.0025 -> 0 | O41: =+$C41*0.0025 -> 0 | P41: =C41*1/120 -> 0 | Q41: =IF(C41<>0,N41*VLOOKUP($D$6,FB_COST,3,FALSE),0) -> 0 | R41: =ISNUMBER(MATCH("TNT_"&B41,TINTED!$B$1:$Y$1,0)) -> FALSE | S41: =ISNUMBER(MATCH("GLT_"&B41,GLITTERED!$B$1:$S$1,0)) -> FALSE | U41: =ISNUMBER(MATCH("BC_"&B41,BICOLOR!$B$1:$Y$1,0)) -> FALSE | W41: =IFERROR(IF(VLOOKUP(D41,FL_COST_COL,2,FALSE)="USA","USA","COL"),"") | X41: =IF(K41<>"","$","NO") -> NO | Y41: =IF(Y40="no_wp",TRUE,FALSE) -> TRUE | Z41: =IF(AA40="Y","WP Pack Type","") | AA41: WP - REG | AC41: CUFT | AD41: =IF(AA40="y",VLOOKUP(AA42,CASES,4,FALSE),"") | AG41: HAND LABOR | AH41: =IF(AND($AA$40="y",$Y$43="WP"),(VLOOKUP(AH39&" _ "&$AA$41,LIST!$A$183:$J$224,MATCH($D$6,LIST!$A$182:$J$182,0),FALSE)-VLOOKUP($AA$42,LIST!$A$130:$H$141,5,FALSE)-VLOOKUP($AA$42,LIST!$A$130:$H$141,8,FALSE))/$AB$45,IF(AND($AA$40="y",$Y$43="ARR"),VLOOKUP(AH39&" _ "&$AA$41,LIST!$A$183:$J$224,MATCH($D$6,LIST!$A$182:$J$182,0),FALSE),0)) -> 0 | AN41: =IF(AM41<>"",AM41*IF($AA$40="y",VLOOKUP($AA$42,CASES,4,FALSE),IF($AA$40="n",VLOOKUP($Z$6,DP_FB_RELATION,4,FALSE))),"")
...

Sheet CUST DATAB
B1: LINK | C1: Customer | D1: Warehouse | E1: Store | F1: DEL COST / CUBE
A2: =IF(C2=C1,A1+1,1) -> 1 | B2: =A2&"-"&C2 -> 1-365 BY WHOLE FOODS | C2: 365 BY WHOLE FOODS | D2: CALIFORNIA | E2: 365 BY WHOLE FOODS CEDAR PARK | F2: TO BE DEFINE
A3: =IF(C3=C2,A2+1,1) -> 1 | B3: =A3&"-"&C3 -> 1-NEW CUSTOMER | C3: NEW CUSTOMER | D3: MIAMI | E3: NEW CUSTOMER MIAMI | F3: 0
A4: =IF(C4=C3,A3+1,1) -> 2 | B4: =A4&"-"&C4 -> 2-NEW CUSTOMER | C4: NEW CUSTOMER | D4: NEW JERSEY | E4: NEW CUSTOMER NEW JERSEY | F4: 0
A5: =IF(C5=C4,A4+1,1) -> 3 | B5: =A5&"-"&C5 -> 3-NEW CUSTOMER | C5: NEW CUSTOMER | D5: CALIFORNIA | E5: NEW CUSTOMER CALIFORNIA | F5: 0
A6: =IF(C6=C5,A5+1,1) -> 4 | B6: =A6&"-"&C6 -> 4-NEW CUSTOMER | C6: NEW CUSTOMER | D6: CHICAGO | E6: NEW CUSTOMER CHICAGO | F6: 0
A7: =IF(C7=C6,A6+1,1) -> 5 | B7: =A7&"-"&C7 -> 5-NEW CUSTOMER | C7: NEW CUSTOMER | D7: WASHINGTON | E7: NEW CUSTOMER WASHINGTON | F7: 0
A8: =IF(C8=C7,A7+1,1) -> 1 | B8: =A8&"-"&C8 -> 1-OPEN DESIGN | C8: OPEN DESIGN | D8: MIAMI | E8: OPEN DESIGN MIAMI | F8: 0
A9: =IF(C9=C8,A8+1,1) -> 2 | B9: =A9&"-"&C9 -> 2-OPEN DESIGN | C9: OPEN DESIGN | D9: NEW JERSEY | E9: OPEN DESIGN NEW JERSEY | F9: 0
A10: =IF(C10=C9,A9+1,1) -> 3 | B10: =A10&"-"&C10 -> 3-OPEN DESIGN | C10: OPEN DESIGN | D10: CALIFORNIA | E10: OPEN DESIGN CALIFORNIA | F10: 0
A11: =IF(C11=C10,A10+1,1) -> 4 | B11: =A11&"-"&C11 -> 4-OPEN DESIGN | C11: OPEN DESIGN | D11: CHICAGO | E11: OPEN DESIGN CHICAGO | F11: 0
A12: =IF(C12=C11,A11+1,1) -> 5 | B12: =A12&"-"&C12 -> 5-OPEN DESIGN | C12: OPEN DESIGN | D12: WASHINGTON | E12: OPEN DESIGN WASHINGTON | F12: 0
A13: =IF(C13=C12,A12+1,1) -> 1 | B13: =A13&"-"&C13 -> 1-ABTFW ASSOCIATED WHOLESALE GROCERS | C13: ABTFW ASSOCIATED WHOLESALE GROCERS | D13: MIAMI | E13: ABTFW ASSOCIATED WHOLESALE GROCERS | F13: 2.9
A14: =IF(C14=C13,A13+1,1) -> 1 | B14: =A14&"-"&C14 -> 1-AHOLD | C14: AHOLD | D14: MIAMI | E14: AHOLD OFFICE ACCOUNT | F14: TO BE DEFINE
A15: =IF(C15=C14,A14+1,1) -> 2 | B15: =A15&"-"&C15 -> 2-AHOLD | C15: AHOLD | D15: MIAMI | E15: GIANT OF CARLISLE | F15: TO BE DEFINE
A16: =IF(C16=C15,A15+1,1) -> 3 | B16: =A16&"-"&C16 -> 3-AHOLD | C16: AHOLD | D16: MIAMI | E16: STOP & SHOP FREETOWN - FC#54 | F16: TO BE DEFINE
A17: =IF(C17=C16,A16+1,1) -> 4 | B17: =A17&"-"&C17 -> 4-AHOLD | C17: AHOLD | D17: NEW JERSEY | E17: C & S CHESTER | F17: TO BE DEFINE
A18: =IF(C18=C17,A17+1,1) -> 5 | B18: =A18&"-"&C18 -> 5-AHOLD | C18: AHOLD | D18: NEW JERSEY | E18: PPO OFFICE | F18: TO BE DEFINE
A19: =IF(C19=C18,A18+1,1) -> 1 | B19: =A19&"-"&C19 -> 1-ALBERTSON'S IRVINE | C19: ALBERTSON'S IRVINE | D19: CALIFORNIA | E19: ALBERTSONS IRVINE | F19: TO BE DEFINE
A20: =IF(C20=C19,A19+1,1) -> 1 | B20: =A20&"-"&C20 -> 1-ALBERTSON'S JEWEL | C20: ALBERTSON'S JEWEL | D20: CHICAGO | E20: SUPERVALU JEWEL | F20: 0.3
A21: =IF(C21=C20,A20+1,1) -> 1 | B21: =A21&"-"&C21 -> 1-ALBERTSON'S LANCASTER | C21: ALBERTSON'S LANCASTER | D21: NEW JERSEY | E21: SUPERVALU LANCASTER | F21: TO BE DEFINE
A22: =IF(C22=C21,A21+1,1) -> 2 | B22: =A22&"-"&C22 -> 2-ALBERTSON'S LANCASTER | C22: ALBERTSON'S LANCASTER | D22: NEW JERSEY | E22: SVU LANCASTER, ACME/ALB | F22: TO BE DEFINE
A23: =IF(C23=C22,A22+1,1) -> 1 | B23: =A23&"-"&C23 -> 1-ALBERTSON'S NEWELL & CO | C23: ALBERTSON'S NEWELL & CO | D23: MIAMI | E23: SUPERVALU W. NEWELL & CO. | F23: 2.35
A24: =IF(C24=C23,A23+1,1) -> 1 | B24: =A24&"-"&C24 -> 1-ALBERTSON'S PHOENIX | C24: ALBERTSON'S PHOENIX | D24: MIAMI | E24: ALBERTSON PHOENIX | F24: 3.88
A25: =IF(C25=C24,A24+1,1) -> 1 | B25: =A25&"-"&C25 -> 1-ALBERTSON'S PORTLAND | C25: ALBERTSON'S PORTLAND | D25: CALIFORNIA | E25: ALBERTSON´S PORTLAND | F25: TO BE DEFINE
A26: =IF(C26=C25,A25+1,1) -> 2 | B26: =A26&"-"&C26 -> 2-ALBERTSON'S PORTLAND | C26: ALBERTSON'S PORTLAND | D26: CALIFORNIA | E26: SUPERVALU PORTLAND | F26: TO BE DEFINE
A27: =IF(C27=C26,A26+1,1) -> 1 | B27: =A27&"-"&C27 -> 1-ALBERTSON'S SALT LAKE CITY | C27: ALBERTSON'S SALT LAKE CITY | D27: MIAMI | E27: ALBERTSON´S SALT LAKE CITY | F27: TO BE DEFINE
A28: =IF(C28=C27,A27+1,1) -> 1 | B28: =A28&"-"&C28 -> 1-ALBERTSON'S SHAWS | C28: ALBERTSON'S SHAWS | D28: NEW JERSEY | E28: SHAWS SUPERMARKETS INC | F28: TO BE DEFINE
A29: =IF(C29=C28,A28+1,1) -> 2 | B29: =A29&"-"&C29 -> 2-ALBERTSON'S SHAWS | C29: ALBERTSON'S SHAWS | D29: NEW JERSEY | E29: SHAWS/STAR - ABS | F29: TO BE DEFINE
A30: =IF(C30=C29,A29+1,1) -> 1 | B30: =A30&"-"&C30 -> 1-ASSOCIATED WHOLESALE GROCERS INC | C30: ASSOCIATED WHOLESALE GROCERS INC | D30: MIAMI | E30: ASSOCIATED SPRINGFIELD | F30: TO BE DEFINE
A31: =IF(C31=C30,A30+1,1) -> 1 | B31: =A31&"-"&C31 -> 1-BILO | C31: BILO | D31: MIAMI | E31: BILO / C&S MAULDIN | F31: TO BE DEFINE
A32: =IF(C32=C31,A31+1,1) -> 1 | B32: =A32&"-"&C32 -> 1-BOZZUTO´S IGA INC | C32: BOZZUTO´S IGA INC | D32: NEW JERSEY | E32: BOZZUTOS IGA INC | F32: 1.49
A33: =IF(C33=C32,A32+1,1) -> 2 | B33: =A33&"-"&C33 -> 2-BOZZUTO´S IGA INC | C33: BOZZUTO´S IGA INC | D33: NEW JERSEY | E33: KING KULLEN | F33: TO BE DEFINE
A34: =IF(C34=C33,A33+1,1) -> 1 | B34: =A34&"-"&C34 -> 1-BRISTOL FARMS | C34: BRISTOL FARMS | D34: CALIFORNIA | E34: BRISTOL FARMS | F34: TO BE DEFINE
A35: =IF(C35=C34,A34+1,1) -> 1 | B35: =A35&"-"&C35 -> 1-DBA WESTERN BEEF PRODUCE | C35: DBA WESTERN BEEF PRODUCE | D35: NEW JERSEY | E35: DBA WESTERN BEEF PRODUCE-INV | F35: TO BE DEFINE
A36: =IF(C36=C35,A35+1,1) -> 2 | B36: =A36&"-"&C36 -> 2-DBA WESTERN BEEF PRODUCE | C36: DBA WESTERN BEEF PRODUCE | D36: NEW JERSEY | E36: DSD BRUCKNER BLVD # 062 | F36: TO BE DEFINE
A37: =IF(C37=C36,A36+1,1) -> 3 | B37: =A37&"-"&C37 -> 3-DBA WESTERN BEEF PRODUCE | C37: DBA WESTERN BEEF PRODUCE | D37: NEW JERSEY | E37: DSD WB MORRIS AVE BRONX # 010 | F37: TO BE DEFINE
A38: =IF(C38=C37,A37+1,1) -> 4 | B38: =A38&"-"&C38 -> 4-DBA WESTERN BEEF PRODUCE | C38: DBA WESTERN BEEF PRODUCE | D38: NEW JERSEY | E38: FOOD NATION | F38: TO BE DEFINE
A39: =IF(C39=C38,A38+1,1) -> 1 | B39: =A39&"-"&C39 -> 1-EARTH FARE INC | C39: EARTH FARE INC | D39: MIAMI | E39: EARTH FARE | F39: TO BE DEFINE
A40: =IF(C40=C39,A39+1,1) -> 1 | B40: =A40&"-"&C40 -> 1-EFS FRESH DIRECT, LLC | C40: EFS FRESH DIRECT, LLC | D40: NEW JERSEY | E40: FRESH DIRECT , LLC | F40: TO BE DEFINE
...

Sheet HOUSE MADE BQT CHART
C3: NAME: | D3: PRETTY BQT | X3: STEM COUNT | Y3: =IF(SUM(B:B)<=10,"MUST BE > 10",SUM(B:B)) -> 12 | AA3: FOB FACILITY FINAL PRICE | AD3: =IF(SUM($B$11:$B$35)<=10,"STEMS",AD5+(AD5*AG3)+(SUM($AD$8:$AD$9)*SUM($K$11:$K$35))) -> #N/A | AE3: MARGIN | AG3: 0.1
X5: SUGGESTED PACK (WP) | Y5: =IFERROR(ROUND(1/SUM(N:N),0),0) -> 0 | AA5: TOTAL COST FOB FACILITY | AD5: =Y18+SUM($AA$21:$AA$32) -> #N/A
C6: HOLIDAY : | D6: EVERYDAY
C7: CUSTOMER | D7: TRADER JOE´S | X7: PACK (WP) | Y7: 12
L8: VOL FULL INBOUND | M8: VOL FULL TRANSFER | N8: VOL WP | O8: INBOUND(U$) | P8: TNT | Q8: GLI | R8: TNT + GLI | S8: BIC | AA8: WASTE % | AD8: 0.02
Q9: GLI | S9: GLI | AA9: CREDITS % | AD9: 0.005
B10: STEMS | C10: FLOWER | D10: TINT | E10: GLI | F10: BIC | G10: ORIG | H10: COLOR | I10: USA COST | J10: COST | K10: TOTAL | P10: TNT | T10: ORIGEN | U10: VLOOKUP | V10: USA COST | X10: FLOWER | Y10: COST
A11: =IFERROR(VLOOKUP(C11,LIST!$A$3:$C$61,4,FALSE),"") | B11: 6 | C11: ROSES | H11: RED | J11: =IF(AND(T11<>"USA",U11<>"USA",V11="NO"),IFERROR((VLOOKUP(C11,FL_COST_COL,MATCH(VLOOKUP($D$6,LIST!$A$111:$B$116,2,FALSE),'FL COST'!$A$1:$G$1,0),FALSE)+IF(D11="Y",0.02,0)+IF(E11="Y",0.02,0)),0),IF(AND(T11<>"USA",U11<>"USA",V11="$"),"ERASE USA COST",IF(AND(T11<>"USA",U11="USA",V11="NO"),"SELECT USA",IF(AND(T11<>"USA",U11="USA",V11="$"),"SELECT USA",IF(AND(T11="USA",U11<>"USA",V11="NO"),"USA COST",IF(AND(T11="USA",U11<>"USA",V11="$"),I11,IF(AND(T11="USA",U11="USA",V11="NO"),"USA COST",IF(AND(T11="USA",U11="USA",V11="$"),I11,IF(C11="",""))))))))) -> 0 | K11: =IFERROR(B11*J11,"ERROR") -> 0 | L11: =IF(G11="USA",0,B11*1/VLOOKUP(C11,PACK!A:B,15,FALSE)) -> #N/A | M11: =B11*1/VLOOKUP(C11,PACK!A:B,15,FALSE) -> #N/A | N11: =B11*1/VLOOKUP(C11,PACK!A:B,9,FALSE) -> #N/A | O11: =IF(B11<>0,L11*VLOOKUP($D$6,FB_COST,3,FALSE),0) -> #N/A | P11: =ISNUMBER(MATCH("TNT_"&A11,TINTED!#REF!,0)) -> FALSE | Q11: =ISNUMBER(MATCH("GLT_"&A11,GLITTERED!#REF!,0)) -> FALSE | R11: =ISNUMBER(MATCH("TNT_GLT_"&A11,'TNT-GLT'!$B$1:$O$1,0)) -> FALSE | S11: =ISNUMBER(MATCH("BC_"&A11,BICOLOR!$B$1:$P$1,0)) -> FALSE | T11: =IF(OR(G11="",G11="COL"),"COL","USA") -> COL | U11: =IFERROR(IF(VLOOKUP(C11,FL_COST_COL,2,FALSE)="USA","USA","COL"),"") | V11: =IF(I11<>"","$","NO") -> NO | X11: FLOWER COST FOB COL | Y11: =SUMIFS(K:K,G:G,"COL")+SUMIFS(K:K,G:G,"") -> 0
